Workbook

Sheet Dev Plan — Gap Closure
A1: Development Plan — Closing Gaps to Full Functional Compliance (Progress Update)
A2: Status as of August 7, 2026: 14 of 28 tasks complete and verified (code written, automated tests passing), 1 partially complete, 13 not started. Workstreams A (MPI identity resolution + Provider Access opt-out consent), B (DTR CDex conformance), and E (risk-flag remediation) are fully done. Remaining scope: C, D, F (partial), G, H. Certification path/timeline (other tabs) is unchanged by this update. Rates from the same standard rate card used throughout this workbook.
A4: Status Key
A5: Done | B5: Code written, automated tests passing, verified this session. (14 tasks)
A6: Partial | B6: Meaningful progress made; scope not fully closed. (1 task)
A7: Remaining | B7: Not yet started. (13 tasks)
A9: AI Feasibility Categories
A10: Full Automation | B10: Claude can build/test the feature end-to-end with only light human review.
A11: AI-Assisted | B11: Claude materially speeds up the work, but a human must still decide, validate against real data, or coordinate externally.
A12: Human-Required | B12: Inherently human: business/architecture decisions, external coordination.
A14: Task-Level Plan (Status + Remaining Cost)
A15: ID | B15: Workstream | C15: Task | D15: Owner Role | E15: AI Feasibility | F15: Status | G15: Remaining Days (No AI) | H15: Remaining Days (With AI) | I15: Remaining Cost (No AI, $) | J15: Remaining Cost (With AI, $) | K15: Remaining Savings ($)
A16: A1 | B16: A — Identity Resolution (MPI) | C16: Design cross-source identity-resolution (MPI) matching approach | D16: Tech Lead | E16: AI-Assisted | F16: Done | G16: 0 | H16: 0 | I16: =G16*INDEX('Time & Cost Summary'!$B$6:$B$15,MATCH(D16,'Time & Cost Summary'!$A$6:$A$15,0)) -> 0 | J16: =H16*INDEX('Time & Cost Summary'!$B$6:$B$15,MATCH(D16,'Time & Cost Summary'!$A$6:$A$15,0)) -> 0 | K16: =I16-J16 -> 0
A17: A2 | B17: A — Identity Resolution (MPI) | C17: Build MPI matching engine (deterministic + probabilistic rules) | D17: Data/Integration Engineer | E17: AI-Assisted | F17: Done | G17: 0 | H17: 0 | I17: =G17*INDEX('Time & Cost Summary'!$B$6:$B$15,MATCH(D17,'Time & Cost Summary'!$A$6:$A$15,0)) -> 0 | J17: =H17*INDEX('Time & Cost Summary'!$B$6:$B$15,MATCH(D17,'Time & Cost Summary'!$A$6:$A$15,0)) -> 0 | K17: =I17-J17 -> 0
A18: A3 | B18: A — Identity Resolution (MPI) | C18: Integrate MPI layer with existing $member-match + audit trail | D18: Backend/FHIR Engineer 1 | E18: Full Automation | F18: Done | G18: 0 | H18: 0 | I18: =G18*INDEX('Time & Cost Summary'!$B$6:$B$15,MATCH(D18,'Time & Cost Summary'!$A$6:$A$15,0)) -> 0 | J18: =H18*INDEX('Time & Cost Summary'!$B$6:$B$15,MATCH(D18,'Time & Cost Summary'!$A$6:$A$15,0)) -> 0 | K18: =I18-J18 -> 0
A19: A4 | B19: A — Identity Resolution (MPI) | C19: MPI automated test suite | D19: QA Engineer | E19: Full Automation | F19: Done | G19: 0 | H19: 0 | I19: =G19*INDEX('Time & Cost Summary'!$B$6:$B$15,MATCH(D19,'Time & Cost Summary'!$A$6:$A$15,0)) -> 0 | J19: =H19*INDEX('Time & Cost Summary'!$B$6:$B$15,MATCH(D19,'Time & Cost Summary'!$A$6:$A$15,0)) -> 0 | K19: =I19-J19 -> 0
A20: A5 | B20: A — Identity Resolution (MPI) | C20: Decide MPI integration mode (HCA's existing MPI vs. standalone) | D20: Product/Clinical SME | E20: Human-Required | F20: Remaining | G20: 2 | H20: 1.5 | I20: =G20*INDEX('Time & Cost Summary'!$B$6:$B$15,MATCH(D20,'Time & Cost Summary'!$A$6:$A$15,0)) -> 2600 | J20: =H20*INDEX('Time & Cost Summary'!$B$6:$B$15,MATCH(D20,'Time & Cost Summary'!$A$6:$A$15,0)) -> 1950 | K20: =I20-J20 -> 650
A21: A6 | B21: A — Identity Resolution (MPI) | C21: Build MPI integration-mode adapter layer | D21: Data/Integration Engineer | E21: Full Automation | F21: Done | G21: 0 | H21: 0 | I21: =G21*INDEX('Time & Cost Summary'!$B$6:$B$15,MATCH(D21,'Time & Cost Summary'!$A$6:$A$15,0)) -> 0 | J21: =H21*INDEX('Time & Cost Summary'!$B$6:$B$15,MATCH(D21,'Time & Cost Summary'!$A$6:$A$15,0)) -> 0 | K21: =I21-J21 -> 0
A22: A7 | B22: A — Provider Access Opt-Out Consent | C22: Build consent capture UI for Provider Access opt-out | D22: Frontend Engineer | E22: Full Automation | F22: Done | G22: 0 | H22: 0 | I22: =G22*INDEX('Time & Cost Summary'!$B$6:$B$15,MATCH(D22,'Time & Cost Summary'!$A$6:$A$15,0)) -> 0 | J22: =H22*INDEX('Time & Cost Summary'!$B$6:$B$15,MATCH(D22,'Time & Cost Summary'!$A$6:$A$15,0)) -> 0 | K22: =I22-J22 -> 0
A23: A8 | B23: A — Provider Access Opt-Out Consent | C23: Integrate consent gate into canReadMemberData() authorization check | D23: Backend/FHIR Engineer 2 | E23: Full Automation | F23: Done | G23: 0 | H23: 0 | I23: =G23*INDEX('Time & Cost Summary'!$B$6:$B$15,MATCH(D23,'Time & Cost Summary'!$A$6:$A$15,0)) -> 0 | J23: =H23*INDEX('Time & Cost Summary'!$B$6:$B$15,MATCH(D23,'Time & Cost Summary'!$A$6:$A$15,0)) -> 0 | K23: =I23-J23 -> 0
A24: A9 | B24: A — Provider Access Opt-Out Consent | C24: Build consent revocation flow | D24: Backend/FHIR Engineer 2 | E24: Full Automation | F24: Done | G24: 0 | H24: 0 | I24: =G24*INDEX('Time & Cost Summary'!$B$6:$B$15,MATCH(D24,'Time & Cost Summary'!$A$6:$A$15,0)) -> 0 | J24: =H24*INDEX('Time & Cost Summary'!$B$6:$B$15,MATCH(D24,'Time & Cost Summary'!$A$6:$A$15,0)) -> 0 | K24: =I24-J24 -> 0
A25: A10 | B25: A — Provider Access Opt-Out Consent | C25: Consent flow automated test suite | D25: QA Engineer | E25: Full Automation | F25: Done | G25: 0 | H25: 0 | I25: =G25*INDEX('Time & Cost Summary'!$B$6:$B$15,MATCH(D25,'Time & Cost Summary'!$A$6:$A$15,0)) -> 0 | J25: =H25*INDEX('Time & Cost Summary'!$B$6:$B$15,MATCH(D25,'Time & Cost Summary'!$A$6:$A$15,0)) -> 0 | K25: =I25-J25 -> 0
A26: B1 | B26: B — DTR CDex Conformance | C26: Implement CDex-conformant DocumentReference construction (replace plain file upload) | D26: Backend/FHIR Engineer 1 | E26: Full Automation | F26: Done | G26: 0 | H26: 0 | I26: =G26*INDEX('Time & Cost Summary'!$B$6:$B$15,MATCH(D26,'Time & Cost Summary'!$A$6:$A$15,0)) -> 0 | J26: =H26*INDEX('Time & Cost Summary'!$B$6:$B$15,MATCH(D26,'Time & Cost Summary'!$A$6:$A$15,0)) -> 0 | K26: =I26-J26 -> 0
A27: B2 | B27: B — DTR CDex Conformance | C27: CDex DocumentReference conformance tests | D27: QA Engineer | E27: Full Automation | F27: Done | G27: 0 | H27: 0 | I27: =G27*INDEX('Time & Cost Summary'!$B$6:$B$15,MATCH(D27,'Time & Cost Summary'!$A$6:$A$15,0)) -> 0 | J27: =H27*INDEX('Time & Cost Summary'!$B$6:$B$15,MATCH(D27,'Time & Cost Summary'!$A$6:$A$15,0)) -> 0 | K27: =I27-J27 -> 0
... A43: H2 | B43: H — Documentation & Evidence Refresh | C43: Regenerate RFI evidence citations for a V5 pass | D43: Tech Lead | E43: Full Automation | F43: Remaining | G43: 2 | H43: 0.5 | I43: =G43*INDEX('Time & Cost Summary'!$B$6:$B$15,MATCH(D43,'Time & Cost Summary'!$A$6:$A$15,0)) -> 2900 | J43: =H43*INDEX('Time & Cost Summary'!$B$6:$B$15,MATCH(D43,'Time & Cost Summary'!$A$6:$A$15,0)) -> 725 | K43: =I43-J43 -> 2175
A45: What Shipped / What's Left, by Task
A46: ID | B46: Evidence
A47: A1 | B47: Shipped: deterministic-then-probabilistic design implemented in lib/identity/matchEngine.ts.
A48: A2 | B48: Shipped: lib/identity/matchEngine.ts — exact-ID/name+DOB deterministic rules + weighted (name/DOB/sex/zip/phone) probabilistic scoring. 13 tests passing.
A49: A3 | B49: Shipped: lib/identity/resolveIdentity.ts + lib/server/identityResolution.ts — cross-source resolution, PHI-safe audit events. 8 tests passing.
A50: A4 | B50: Shipped: 21 automated tests across matchEngine.test.ts, resolveIdentity.test.ts, resolveIdentityWithAudit.test.ts.
A51: A5 | B51: Not yet decided — awaiting joint decision with HCA. Blocks final wiring of the mode-specific adapter, not the adapter interface itself.
A52: A6 | B52: Shipped: lib/identity/identitySource.ts — adapter interface + mock implementation, swappable for a real production source once A5 is decided.
A53: A7 | B53: Shipped: consent capture + amber warning block in provider-access page.
A54: A8 | B54: Shipped: providerAccessOptedOut check wired into src/lib/authz/guard.ts (break-glass still overrides, as required).
A55: A9 | B55: Shipped: GET/POST /api/consent/provider-access + ProviderAccessConsentStore.
A56: A10 | B56: Shipped: 8 tests (3 in guard.test.ts + 5 in providerAccessOptOut.test.ts).
A57: B1 | B57: Shipped: PA-Standalone-SmartApp/src/lib/dtr/cdexDocumentReference.ts, wired into the DTR upload flow. This clears the one hard blocker to DTR conformance testing.
... A74: H2 | B74: Not started.
A76: Remaining Dev Plan Cost (Go-Forward, as of Aug 7, 2026)
...

Sheet Dev Plan Gantt
A1: Development Plan — Gantt Chart (Progress Update: 7-Week Remaining Schedule)
A2: Completed tasks (green "DONE" bar) are shown for continuity but no longer consume schedule. Week numbers for remaining tasks are relative to a fresh kickoff of the go-forward plan (kickoff date TBD), not the original 11-week baseline. Bars colored by workstream; AI Feasibility: Green = Claude can execute end-to-end · Yellow = AI-assisted, human decides/validates · Red = inherently human.
A4: ID | B4: Task | C4: Owner | D4: AI Feasibility | E4: Status | F4: Dur (wks) | G4: W1 | H4: W2 | I4: W3 | J4: W4 | K4: W5 | L4: W6 | M4: W7
A5: A — Identity Resolution (MPI)
A6: A1 | B6: Design cross-source identity-resolution (MPI) matching approach | C6: Tech Lead | D6: AI-Assisted | E6: Done | F6: — | G6: ✓ DONE
A7: A2 | B7: Build MPI matching engine (deterministic + probabilistic rules) | C7: Data/Integration Engineer | D7: AI-Assisted | E7: Done | F7: — | G7: ✓ DONE
A8: A3 | B8: Integrate MPI layer with existing $member-match + audit trail | C8: Backend/FHIR Engineer 1 | D8: Full Automation | E8: Done | F8: — | G8: ✓ DONE
A9: A4 | B9: MPI automated test suite | C9: QA Engineer | D9: Full Automation | E9: Done | F9: — | G9: ✓ DONE
A10: A5 | B10: Decide MPI integration mode (HCA's existing MPI vs. standalone) | C10: Product/Clinical SME | D10: Human-Required | E10: Remaining | F10: 1
A11: A6 | B11: Build MPI integration-mode adapter layer | C11: Data/Integration Engineer | D11: Full Automation | E11: Done | F11: — | G11: ✓ DONE
A12: A — Provider Access Opt-Out Consent
A13: A7 | B13: Build consent capture UI for Provider Access opt-out | C13: Frontend Engineer | D13: Full Automation | E13: Done | F13: — | G13: ✓ DONE
A14: A8 | B14: Integrate consent gate into canReadMemberData() authorization check | C14: Backend/FHIR Engineer 2 | D14: Full Automation | E14: Done | F14: — | G14: ✓ DONE
A15: A9 | B15: Build consent revocation flow | C15: Backend/FHIR Engineer 2 | D15: Full Automation | E15: Done | F15: — | G15: ✓ DONE
A16: A10 | B16: Consent flow automated test suite | C16: QA Engineer | D16: Full Automation | E16: Done | F16: — | G16: ✓ DONE
A17: B — DTR CDex Conformance
A18: B1 | B18: Implement CDex-conformant DocumentReference construction (replace plain file upload) | C18: Backend/FHIR Engineer 1 | D18: Full Automation | E18: Done | F18: — | G18: ✓ DONE
A19: B2 | B19: CDex DocumentReference conformance tests | C19: QA Engineer | D19: Full Automation | E19: Done | F19: — | G19: ✓ DONE
A20: C — Provider Access Bulk Export Hardening
A21: C1 | B21: Exercise SMART Backend Services bulk export end-to-end against staging | C21: Backend/FHIR Engineer 2 | D21: AI-Assisted | E21: Remaining | F21: 2
A22: C2 | B22: Volume/load testing for 5-year look-back scoped exports | C22: QA Engineer | D22: Full Automation | E22: Remaining | F22: 2
A23: C3 | B23: Add monitoring/alerting hooks for bulk export jobs | C23: Backend/FHIR Engineer 2 | D23: Full Automation | E23: Remaining | F23: 2
A24: D — Policy Monitoring Mode
A25: D1 | B25: Build policy-library change watcher | C25: Data/Integration Engineer | D25: Full Automation | E25: Remaining | F25: 2
A26: D2 | B26: Build proposed-update workflow (structured-resource diffs for human approval) | C26: Backend/FHIR Engineer 1 | D26: Full Automation | E26: Remaining | F26: 2
A27: D3 | B27: Build human-approval UI for proposed policy updates | C27: Frontend Engineer | D27: Full Automation | E27: Remaining | F27: 2
A28: D4 | B28: Policy monitoring automated test suite | C28: QA Engineer | D28: Full Automation | E28: Remaining | F28: 2
A29: E — Risk-Flag Remediation
A30: E1 | B30: Fix "Propensity-to-deny" UI copy across 4 screens to "submission-readiness (completeness) score" | C30: Frontend Engineer | D30: Full Automation | E30: Done | F30: — | G30: ✓ DONE
A31: E2 | B31: Scope & exclude unrelated client modules (uhg-orchestrate, md-smart-launch) from any HCA-facing build | C31: Tech Lead | D31: AI-Assisted | E31: Done | F31: — | G31: ✓ DONE
A32: E3 | B32: Restore missing Postman contract-test collection referenced by test:contract script | C32: QA Engineer | D32: Full Automation | E32: Done | F32: — | G32: ✓ DONE
A33: F — Test Coverage Hardening
A34: F1 | B34: Expand PA-Standalone-SmartApp test suite (was 1 test) to match main-app rigor | C34: QA Engineer | D34: Full Automation | E34: Partial | F34: 2
A35: G — Environment & Cutover Readiness
A36: G1 | B36: Live backbone staging integration — engineering | C36: Backend/FHIR Engineer 1 | D36: AI-Assisted | E36: Remaining | F36: 3
A37: G2 | B37: Live backbone staging integration — data mapping | C37: Data/Integration Engineer | D37: AI-Assisted | E37: Remaining | F37: 3
A38: G3 | B38: End-to-end Golden Thread regression pass after all gap-closure changes | C38: QA Engineer | D38: Full Automation | E38: Remaining | F38: 2
A39: H — Documentation & Evidence Refresh
A40: H1 | B40: Update conformance-plan.md and internal docs to reflect closed gaps | C40: Tech Lead | D40: Full Automation | E40: Remaining | F40: 1
A41: H2 | B41: Regenerate RFI evidence citations for a V5 pass | C41: Tech Lead | D41: Full Automation | E41: Remaining | F41: 1
...

Sheet Project Plan
A1: Standards-Conformance Testing — Project Plan
A2: CMS-0057-F prior-authorization platform — closing the Section 5.6 Testing Approach gap identified in the RFI code audit
A4: Phase | B4: Task ID | C4: Task | D4: Owner | E4: Duration | F4: Dependencies | G4: Deliverable / Exit Criteria | H4: Status
A5: Phase 0 — Governance & Scoping (Week 1–2)
A6: Phase 0 | B6: 0.1 | C6: Confirm target IG versions to test against (CRD 2.2.1, DTR 2.0.1, PAS 2.0.1, US Core 6.1.0/7.0.0, CARIN BB 2.0.0/2.1.0, SMART App Launch STU2.2) and lock scope | D6: Solution Architect | E6: 3 days | F6: — | G6: Signed-off conformance scope memo | H6: Not started
A7: Phase 0 | B7: 0.2 | C7: Stand up a dedicated conformance test environment pointed at the live/staging backbone (not the mock reference environment) using the existing config-based cutover | D7: Platform Engineering | E7: 1 week | F7: 0.1 | G7: isBackboneConfigured() = true in a stable staging tenancy | H7: Not started
A8: Phase 0 | B8: 0.3 | C8: Identify and engage one real or sandbox trading-partner payer/clearinghouse for X12 278/275 round-trip testing | D8: Delivery Lead | E8: 1–2 weeks | F8: — | G8: Signed trading-partner test agreement | H8: Not started
A9: Phase 0 | B9: 0.4 | C9: Assign an internal conformance owner per suite (CRD/DTR/PAS, US Core, CARIN BB, SMART, X12) accountable for pass/fail and remediation | D9: Delivery Lead | E9: 2 days | F9: — | G9: RACI published | H9: Not started
A10: Phase 1 — FHIR Conformance: Foundational IGs (Week 2–5, parallel)
A11: Phase 1 | B11: 1.1 | C11: Run Inferno US Core Test Kit (server suite) against staging FHIR endpoints for Coverage, Condition, Claim/ClaimResponse, QuestionnaireResponse, Consent, Provenance | D11: Platform Engineering | E11: 1 week | F11: 0.2 | G11: Inferno results export — 0 required-test failures | H11: Not started
A12: Phase 1 | B12: 1.2 | C12: Run Inferno SMART App Launch Test Kit against the DTR SMART app's authorization flow | D12: Platform Engineering | E12: 3 days | F12: 0.2 | G12: Inferno results export — passing launch + token flows | H12: Not started
A13: Phase 1 | B13: 1.3 | C13: Run Inferno CARIN IG for Blue Button Test Kit against the Patient Access API server | D13: Platform Engineering | E13: 1 week | F13: 0.2, 1.1 | G13: Inferno results export — passing server suite | H13: Not started
A14: Phase 1 | B14: 1.4 | C14: Remediate and re-run any failing US Core / SMART / CARIN required tests | D14: Platform Engineering | E14: 1–2 weeks | F14: 1.1–1.3 | G14: Clean re-test with 0 required-test failures | H14: Not started
A15: Phase 2 — FHIR Conformance: Da Vinci Prior-Auth IGs (Week 4–8, parallel with Phase 1 tail)
A16: Phase 2 | B16: 2.1 | C16: Run Inferno Da Vinci CRD Test Kit against the CDS Hooks order-select/order-sign services | D16: Platform Engineering | E16: 1–2 weeks | F16: 0.2 | G16: Inferno results export — passing CRD client/server suite | H16: Not started
A17: Phase 2 | B17: 2.2 | C17: Run Inferno Da Vinci DTR Test Kit against the DTR SMART app + Questionnaire Package retrieval | D17: Platform Engineering | E17: 1–2 weeks | F17: 1.2, 0.2 | G17: Inferno results export — passing DTR suite | H17: Not started
A18: Phase 2 | B18: 2.3 | C18: Run Inferno Da Vinci PAS Test Kit against PASBundle submission and status-update handling (note: ONC's PAS kit is published in draft/preliminary status — expect to log implementer feedback to HL7/ONC as part of this run) | D18: Platform Engineering | E18: 2 weeks | F18: 0.2 | G18: Inferno results export — passing PAS suite; feedback filed with ONC if gaps found in the kit itself | H18: Not started
A19: Phase 2 | B19: 2.4 | C19: Remediate and re-run any failing CRD / DTR / PAS required tests | D19: Platform Engineering | E19: 2–3 weeks | F19: 2.1–2.3 | G19: Clean re-test with 0 required-test failures | H19: Not started
A20: Phase 2 | B20: 2.5 | C20: (Optional, recommended) Register for an upcoming HL7 Da Vinci Connectathon track (CRD/DTR/PAS) to test interoperability against independent implementers, not just Inferno's simulated client/server | D20: Solution Architect | E20: 1 connectathon cycle (~1 week event + prep) | F20: 2.4 | G20: Published connectathon participation / track results | H20: Not started
A21: Phase 3 — X12 278/275 Conformance (Week 3–8, parallel)
A22: Phase 3 | B22: 3.1 | C22: Execute X12 278 (request/response) transaction testing against the engaged trading partner per Phase 0.3, validating against the TR3 companion guide | D22: Integration Engineering | E22: 2–3 weeks | F22: 0.3, 0.2 | G22: Clean 278 request/response pairs, no syntax or balancing errors | H22: Not started
A23: Phase 3 | B23: 3.2 | C23: Execute X12 275 (attachment) transaction testing for DTR-equivalent documentation exchange over the EDI channel | D23: Integration Engineering | E23: 1–2 weeks | F23: 3.1 | G23: Clean 275 exchange validated by trading partner | H23: Not started
A24: Phase 3 | B24: 3.3 | C24: Validate conformance to CAQH CORE Prior Authorization & Referrals (278) Infrastructure Rule (vPA.3.0) and Data Content Rule (vPA.1.0) | D24: Integration Engineering | E24: 2 weeks | F24: 3.1, 3.2 | G24: Internal conformance checklist passed against both CORE rules | H24: Not started
A25: Phase 3 | B25: 3.4 | C25: Remediate and re-test any X12/CORE gaps | D25: Integration Engineering | E25: 1–2 weeks | F25: 3.3 | G25: Clean re-test | H25: Not started
A26: Phase 4 — Formal Certification Pursuit (Week 8–16, gated on Phases 1–3 passing)
A27: Phase 4 | B27: 4.1 | C27: Legal/product review: determine which side of each Da Vinci transaction (provider-facing vs. payer-facing) the platform should certify under the new ONC §170.315(g)(31)/(g)(32)/(g)(33) Provider Prior Authorization API criteria, given the platform's role varies by provision | D27: Product + Legal | E27: 1–2 weeks | F27: 2.4 | G27: Written scoping decision on which components pursue ONC certification | H27: Not started
A28: Phase 4 | B28: 4.2 | C28: Engage an ONC-Authorized Certification Body (e.g., Drummond Group, SLI Compliance, or CCHIT/ICSA) for formal §170.315(g)(31)/(g)(32)/(g)(33) certification testing | D28: Delivery Lead | E28: 2–4 weeks (ACB-dependent) | F28: 4.1 | G28: Signed ONC-ACB testing engagement | H28: Not started
A29: Phase 4 | B29: 4.3 | C29: Complete ONC-ACB witnessed testing and remediation cycles | D29: Platform Engineering | E29: 4–6 weeks | F29: 4.2 | G29: ONC-ACB certification decision issued | H29: Not started
A30: Phase 4 | B30: 4.4 | C30: Confirm listing on the federal Certified Health IT Product List (CHPL) | D30: Delivery Lead | E30: 1 week (post-decision) | F30: 4.3 | G30: Public CHPL listing — verifiable by any evaluator, including HCA | H30: Not started
A31: Phase 4 | B31: 4.5 | C31: Pursue CAQH CORE Certification for the Prior Authorization & Referrals (278) Operating Rules through an approved CORE certification testing vendor | D31: Integration Engineering | E31: 4–6 weeks | F31: 3.4 | G31: CAQH CORE Certification Seal issued | H31: Not started
A32: Phase 4 | B32: 4.6 | C32: Sign the CARIN Alliance Code of Conduct for the Patient Access API and register on MyHealthApplication.com | D32: Product + Legal | E32: 1–2 weeks | F32: 1.4 | G32: Public listing under the CARIN Code of Conduct | H32: Not started
A33: Phase 5 — Publish & Report (Week 16–17)
A34: Phase 5 | B34: 5.1 | C34: Compile a public-facing conformance summary (Inferno pass results, connectathon participation, CHPL listing, CAQH CORE seal, CARIN attestation) for use in proposals and demos | D34: Delivery Lead | E34: 3 days | F34: 4.1–4.6 | G34: Conformance & Certification one-pager | H34: Not started
A35: Phase 5 | B35: 5.2 | C35: Update the RFI/proposal Testing Approach section and internal conformance-plan.md to reflect completed (not planned) conformance status | D35: Solution Architect | E35: 2 days | F35: 5.1 | G35: Updated response language, code-evidence-accurate | H35: Not started
A36: Phase 5 | B36: 5.3 | C36: Establish a recurring re-test cadence (e.g., on each IG version bump or annually) to keep conformance evidence current | D36: Delivery Lead | E36: 2 days | F36: 5.1 | G36: Documented re-test schedule | H36: Not started

Sheet Certifications & Recognition
A1: Certification & Recognition Options — What Actually Exists Today (Aug 2026)
A3: Option | B3: What it proves | C3: Status / availability | D3: Path to obtain | E3: Est. cost/effort | F3: Recommendation
A4: ONC Health IT Certification — §170.315(g)(31)/(g)(32)/(g)(33) Provider Prior Authorization API (CRD/DTR/PAS) | B4: Federal, government-run certification that the platform's CRD/DTR/PAS implementation conforms to the Da Vinci IGs — the same standard CMS-0057-F cites. Results in a public listing anyone (including HCA) can verify. | C4: REAL and current. Finalized in the HTI-4 Final Rule, effective Oct 1, 2025. Very new — few vendors have pursued it yet. | D4: Engage an ONC-Authorized Certification Body (ONC-ACB, e.g., Drummond Group, SLI Compliance) for witnessed testing; passing results in listing on the federal Certified Health IT Product List (CHPL). | E4: Moderate — typically weeks to a few months and a mid-five-figure testing fee, ACB-dependent | F4: PURSUE — strongest, most credible, government-issued proof available; being early is a differentiator
A5: Payer-side FHIR API certification (was proposed under HTI-2) | B5: Would have been the direct federal certification for a payer/state-agency-facing PA platform's FHIR APIs. | C5: DOES NOT EXIST. ASTP/ONC withdrew the unfinalized HTI-2 payer-API certification proposals in Dec 2025, pivoting to a deregulatory HTI-5 proposal instead. | D5: Not currently obtainable — no application path exists. Monitor HTI-5 rulemaking in case a voluntary payer pathway re-emerges. | E5: N/A | F5: DO NOT CLAIM — be explicit in the RFI that no such certification currently exists; this is a fact about the regulatory landscape, not a platform gap
A6: Inferno conformance test results (self-service) | B6: Verifiable, third-party-tool pass/fail evidence against US Core, SMART App Launch, CARIN Blue Button, Da Vinci CRD/DTR/PAS. | C6: REAL, free, and operational today at inferno.healthit.gov — the same tool ONC itself uses for certification testing. | D6: Run directly — no application or fee. Publish the results export. | E6: Low — engineering time only (see Project Plan, Phases 1–2) | F6: PURSUE FIRST — fastest, cheapest, most direct way to close the current Testing Approach gap
A7: CAQH CORE Certification — Prior Authorization & Referrals (278) Operating Rules | B7: Industry-standard certification for the X12 278/275 legacy EDI channel; real trading partners (e.g., Availity) hold this seal. | C7: REAL and current (Infrastructure Rule vPA.3.0, Data Content Rule vPA.1.0). | D7: Certification testing through a CAQH CORE-approved testing vendor. | E7: Moderate — several weeks and a testing-vendor fee | F7: PURSUE — closes the X12 278/275 half of the conformance scope with a recognized industry seal
A8: HL7 Da Vinci Connectathon participation (CRD/DTR/PAS tracks) | B8: Real-world interoperability testing against independent implementers, not a simulated test client. | C8: REAL — ongoing HL7 FHIR Connectathons run these tracks regularly. | D8: Register for an upcoming connectathon; HL7 tracks and can publish participation/results. | E8: Low — mainly staff time for a ~1-week event | F8: RECOMMENDED complement — strong signal to standards-literate evaluators, cheap to obtain
A9: CARIN Alliance Code of Conduct attestation | B9: Public, voluntary attestation to consumer-data-sharing best practices for the Patient Access API. | C9: REAL — administered by the CARIN Alliance; attestors listed at MyHealthApplication.com. | D9: Sign the Code of Conduct and register the application. | E9: Low | F9: RECOMMENDED — low-cost, relevant specifically to Patient Access
A10: SOC 2 Type II | B10: Independent audit of security controls (not FHIR/interoperability conformance). | C10: Already referenced in the RFI as an open item — [IBM to insert current SOC 2 report date]. | D10: Standard annual audit cycle via IBM's existing compliance program. | E10: N/A — existing program | F10: ALREADY IN PLAN — close the placeholder with the current report date
A11: HITRUST CSF certification | B11: Higher-bar security/privacy certification, common in healthcare. | C11: Already referenced in the RFI as available if HCA requires it. | D11: Optional add-on assessment. | E11: Higher — significant assessment effort | F11: OPTIONAL — offer only if HCA specifically requires it

Sheet Test Kit Reference
A1: Inferno Test Kit Reference (inferno.healthit.gov)
A3: Test Kit | B3: IG Version(s) Supported | C3: What It Tests | D3: Kit Status | E3: Link
A4: US Core | B4: v3.1.1, v4.0.0, v5.0.1, v6.1.0, v7.0.0, v8.0.0 | C4: Server/client conformance for Coverage, Condition, Claim/ClaimResponse, and other US Core profiles underlying Patient/Provider Access | D4: Stable | E4: https://inferno.healthit.gov/test-kits/us-core/
A5: SMART App Launch | B5: STU1, STU2, STU2.2 | C5: Authorization-server and client conformance for the DTR SMART app launch flow | D5: Stable | E5: https://inferno.healthit.gov/test-kits/smart-app-launch/
A6: CARIN IG for Blue Button | B6: v2.0.0 / v2.1.0 | C6: Server/client conformance for the Patient Access consumer-directed data API | D6: Stable | E6: https://inferno.healthit.gov/test-kits/carin-for-blue-button/
A7: Da Vinci CRD | B7: STU 2.0.1, STU 2.2.1 | C7: Coverage Requirements Discovery client/server conformance (CDS Hooks order-select/sign) | D7: Stable, actively updated (2026 US Quality Core IG update noted) | E7: https://inferno.healthit.gov/test-kits/davinci-crd/
A8: Da Vinci DTR | B8: v2.0.1 | C8: Documentation Templates & Rules SMART app client and payer server conformance | D8: Stable | E8: https://inferno.healthit.gov/test-kits/davinci-dtr/
A9: Da Vinci PAS | B9: v2.0.1 | C9: Prior Authorization Support client/server conformance (PASBundle submission) | D9: Draft / preliminary — ONC invites implementer feedback | E9: https://inferno.healthit.gov/test-kits/davinci-pas/
A10: ONC Certification (g)(10) Standardized API | B10: Per ONC Certification Program | C10: Combined suite used in formal ONC certification testing | D10: Stable | E10: https://inferno.healthit.gov/test-kits/onc-certification-g10/
A12: Sources: inferno.healthit.gov/test-kits/ ; healthit.gov HTI-4 Final Rule fact sheets (Oct 2025) ; Federal Register HTI-2 Withdrawal notice (Dec 29, 2025) ; caqh.org/core ; carinalliance.com/code-of-conduct. Verified via web search, Aug 2026.

Sheet Gantt Chart
A1: Standards-Conformance Testing — Gantt Chart (18-Week Illustrative Schedule)
A2: Week numbers are relative to project kickoff (kickoff date TBD). Bars are colored by phase. AI Feasibility: Green = Claude can execute end-to-end · Yellow = AI-assisted, human decides/reviews · Red = inherently human (relationship, signature, witnessed session). See AI Impact Analysis tab for detail.
A4: ID | B4: Task | C4: Owner | D4: AI Feasibility | E4: Dur (wks) | F4: W1 | G4: W2 | H4: W3 | I4: W4 | J4: W5 | K4: W6 | L4: W7 | M4: W8 | N4: W9 | O4: W10 | P4: W11 | Q4: W12 | R4: W13 | S4: W14 | T4: W15 | U4: W16 | V4: W17 | W4: W18
A5: Phase 0 — Governance & Scoping
A6: 0.1 | B6: Confirm target IG versions & lock scope | C6: Tech Lead | D6: AI-Assisted | E6: 1
A7: 0.2 | B7: Stand up dedicated conformance test environment | C7: Backend/FHIR Engineer 1 | D7: Full Automation | E7: 2
A8: 0.3 | B8: Engage trading partner for X12 278/275 testing | C8: Project Manager | D8: Human-Required | E8: 2
A9: 0.4 | B9: Assign conformance owner per suite | C9: Project Manager | D9: Human-Required | E9: 1
A10: Phase 1 — Foundational IGs
A11: 1.1 | B11: Run Inferno US Core Test Kit | C11: Backend/FHIR Engineer 1 | D11: Full Automation | E11: 2
A12: 1.2 | B12: Run Inferno SMART App Launch Test Kit | C12: Backend/FHIR Engineer 1 | D12: Full Automation | E12: 2
A13: 1.3 | B13: Run Inferno CARIN Blue Button Test Kit | C13: Backend/FHIR Engineer 2 | D13: Full Automation | E13: 2
A14: 1.4 | B14: Remediate & re-run foundational IG failures | C14: Backend/FHIR Engineer 2 | D14: Full Automation | E14: 2
A15: Phase 2 — Da Vinci Prior-Auth IGs
A16: 2.1 | B16: Run Inferno Da Vinci CRD Test Kit | C16: Backend/FHIR Engineer 1 | D16: Full Automation | E16: 3
A17: 2.2 | B17: Run Inferno Da Vinci DTR Test Kit | C17: Backend/FHIR Engineer 2 | D17: Full Automation | E17: 3
A18: 2.3 | B18: Run Inferno Da Vinci PAS Test Kit | C18: Backend/FHIR Engineer 1 | D18: AI-Assisted | E18: 3
A19: 2.4 | B19: Remediate & re-run CRD/DTR/PAS failures | C19: Backend/FHIR Engineer 2 | D19: AI-Assisted | E19: 3
A20: 2.5 | B20: Participate in CMS HL7 FHIR Connectathon (CRD/DTR/PAS tracks) | C20: Tech Lead | D20: Human-Required | E20: 2
A21: Phase 3 — X12 278/275 Conformance
A22: 3.1 | B22: X12 278 request/response testing with trading partner | C22: Data/Integration Engineer | D22: AI-Assisted | E22: 4
A23: 3.2 | B23: X12 275 attachment testing | C23: Data/Integration Engineer | D23: AI-Assisted | E23: 2
A24: 3.3 | B24: Validate against CAQH CORE 278 Infrastructure & Data Content Rules | C24: Data/Integration Engineer | D24: Full Automation | E24: 3
A25: 3.4 | B25: Remediate & re-test X12/CORE gaps | C25: Data/Integration Engineer | D25: AI-Assisted | E25: 2
A26: Phase 4 — Formal Certification Pursuit
A27: 4.1 | B27: Legal/product scoping — which side of each transaction to certify | C27: Product/Clinical SME | D27: AI-Assisted | E27: 2
A28: 4.2 | B28: Engage ONC-Authorized Certification Body (ONC-ACB) | C28: Project Manager | D28: Human-Required | E28: 4
A29: 4.3 | B29: Complete ONC-ACB witnessed testing & remediation | C29: Backend/FHIR Engineer 1 | D29: AI-Assisted | E29: 6
A30: 4.4 | B30: Confirm CHPL listing | C30: Project Manager | D30: Human-Required | E30: 2
A31: 4.5 | B31: Pursue CAQH CORE Certification (278 Operating Rules) | C31: Data/Integration Engineer | D31: AI-Assisted | E31: 5
A32: 4.6 | B32: Sign CARIN Alliance Code of Conduct | C32: Product/Clinical SME | D32: Human-Required | E32: 2
A33: Phase 5 — Publish & Report
A34: 5.1 | B34: Compile public conformance & certification summary | C34: Project Manager | D34: Full Automation | E34: 2
A35: 5.2 | B35: Update RFI/proposal Testing Approach language | C35: Tech Lead | D35: Full Automation | E35: 1
A36: 5.3 | B36: Establish recurring re-test cadence | C36: Project Manager | D36: AI-Assisted | E36: 1
A38: Phase Legend:
B39: Phase 0 — Governance & Scoping
B40: Phase 1 — Foundational IGs
B41: Phase 2 — Da Vinci Prior-Auth IGs
B42: Phase 3 — X12 278/275 Conformance
...

Sheet Time & Cost Summary
A1: Standards-Conformance Testing — Time & Cost Summary
A2: Labor priced against IBM's standard blended rate card (Source: Prior_Auth_Cost_Model V2.0.xlsx, Assumptions tab). Third-party fees are publicly sourced where available; unpublished vendor fees are labeled as request-a-quote placeholders — replace before using in a firm proposal.
A4: Standard Rate Card ($/day, blended)
A5: Role | B5: Daily Rate ($)
A6: Tech Lead | B6: 1450
A7: Backend/FHIR Engineer 1 | B7: 1100
A8: Backend/FHIR Engineer 2 | B8: 1100
A9: Data/Integration Engineer | B9: 1100
A10: Frontend Engineer | B10: 1000
A11: QA Engineer | B11: 900
A12: Security Engineer | B12: 1250
A13: Product/Clinical SME | B13: 1300
A14: Project Manager | B14: 1050
A15: Clinical Policy Reviewer | B15: 950
A17: Task-Level Cost Detail
A18: ID | B18: Phase | C18: Task | D18: Owner Role | E18: Person-Days | F18: Daily Rate ($) | G18: Task Cost ($)
A19: 0.1 | B19: Phase 0 — Governance & Scoping | C19: Confirm target IG versions & lock scope | D19: Tech Lead | E19: 2 | F19: =INDEX($B$6:$B$15,MATCH(D19,$A$6:$A$15,0)) -> 1450 | G19: =E19*F19 -> 2900
A20: 0.2 | B20: Phase 0 — Governance & Scoping | C20: Stand up dedicated conformance test environment | D20: Backend/FHIR Engineer 1 | E20: 4 | F20: =INDEX($B$6:$B$15,MATCH(D20,$A$6:$A$15,0)) -> 1100 | G20: =E20*F20 -> 4400
A21: 0.3 | B21: Phase 0 — Governance & Scoping | C21: Engage trading partner for X12 278/275 testing | D21: Project Manager | E21: 2 | F21: =INDEX($B$6:$B$15,MATCH(D21,$A$6:$A$15,0)) -> 1050 | G21: =E21*F21 -> 2100
A22: 0.4 | B22: Phase 0 — Governance & Scoping | C22: Assign conformance owner per suite | D22: Project Manager | E22: 1 | F22: =INDEX($B$6:$B$15,MATCH(D22,$A$6:$A$15,0)) -> 1050 | G22: =E22*F22 -> 1050
A23: 1.1 | B23: Phase 1 — Foundational IGs | C23: Run Inferno US Core Test Kit | D23: Backend/FHIR Engineer 1 | E23: 4 | F23: =INDEX($B$6:$B$15,MATCH(D23,$A$6:$A$15,0)) -> 1100 | G23: =E23*F23 -> 4400
A24: 1.2 | B24: Phase 1 — Foundational IGs | C24: Run Inferno SMART App Launch Test Kit | D24: Backend/FHIR Engineer 1 | E24: 2 | F24: =INDEX($B$6:$B$15,MATCH(D24,$A$6:$A$15,0)) -> 1100 | G24: =E24*F24 -> 2200
A25: 1.3 | B25: Phase 1 — Foundational IGs | C25: Run Inferno CARIN Blue Button Test Kit | D25: Backend/FHIR Engineer 2 | E25: 4 | F25: =INDEX($B$6:$B$15,MATCH(D25,$A$6:$A$15,0)) -> 1100 | G25: =E25*F25 -> 4400
A26: 1.4 | B26: Phase 1 — Foundational IGs | C26: Remediate & re-run foundational IG failures | D26: Backend/FHIR Engineer 2 | E26: 6 | F26: =INDEX($B$6:$B$15,MATCH(D26,$A$6:$A$15,0)) -> 1100 | G26: =E26*F26 -> 6600
A27: 2.1 | B27: Phase 2 — Da Vinci Prior-Auth IGs | C27: Run Inferno Da Vinci CRD Test Kit | D27: Backend/FHIR Engineer 1 | E27: 6 | F27: =INDEX($B$6:$B$15,MATCH(D27,$A$6:$A$15,0)) -> 1100 | G27: =E27*F27 -> 6600
A28: 2.2 | B28: Phase 2 — Da Vinci Prior-Auth IGs | C28: Run Inferno Da Vinci DTR Test Kit | D28: Backend/FHIR Engineer 2 | E28: 6 | F28: =INDEX($B$6:$B$15,MATCH(D28,$A$6:$A$15,0)) -> 1100 | G28: =E28*F28 -> 6600
A29: 2.3 | B29: Phase 2 — Da Vinci Prior-Auth IGs | C29: Run Inferno Da Vinci PAS Test Kit | D29: Backend/FHIR Engineer 1 | E29: 8 | F29: =INDEX($B$6:$B$15,MATCH(D29,$A$6:$A$15,0)) -> 1100 | G29: =E29*F29 -> 8800
A30: 2.4 | B30: Phase 2 — Da Vinci Prior-Auth IGs | C30: Remediate & re-run CRD/DTR/PAS failures | D30: Backend/FHIR Engineer 2 | E30: 10 | F30: =INDEX($B$6:$B$15,MATCH(D30,$A$6:$A$15,0)) -> 1100 | G30: =E30*F30 -> 11000
... A44: 5.3 | B44: Phase 5 — Publish & Report | C44: Establish recurring re-test cadence | D44: Project Manager | E44: 1 | F44: =INDEX($B$6:$B$15,MATCH(D44,$A$6:$A$15,0)) -> 1050 | G44: =E44*F44 -> 1050
F45: Labor Subtotal: | G45: =SUM(G19:G44) -> 130200
D46: Total Person-Days: | E46: =SUM(E19:E44) -> 115
A47: External / Third-Party Certification Fees
A48: Item | B48: Est. Fee ($) | C48: Basis / Source
A49: ONC-ACB certification testing — §170.315(g)(31)/(g)(32)/(g)(33) | B49: 35000 | C49: Quote-based; not publicly published. Illustrative placeholder based on reported minimum engagements (~$5,000+) and hourly rates (~$200–300/hr) scaled for a 3-criteria FHIR API scope. Request formal quote from an ONC-ACB (e.g., Drummond Group, SLI Compliance).
A50: CAQH CORE Certification Seal — Prior Authorization & Referrals (278) | B50: 6000 | C50: Published CAQH fee schedule: $4,000 (entities <$75M net annual revenue) or $6,000 (>=$75M); no charge for federal/state government entities. IBM assumed at the $6,000 tier.
A51: CAQH CORE-authorized testing vendor fee | B51: 10000 | C51: Set independently by the CORE-authorized testing vendor, not published by CAQH CORE. Illustrative placeholder — request vendor quote.
A52: HL7 CMS FHIR Connectathon (CRD/DTR/PAS tracks) | B52: 0 | C52: The CMS HL7 FHIR Connectathon is a free, virtual event (confirmed 2026 dates: July 14–16, 2026). No registration fee; only staff time, already captured in labor above.
A53: CARIN Alliance Code of Conduct attestation | B53: 0 | C53: Voluntary, no-fee attestation administered by the CARIN Alliance.
A54: Incremental test-environment infrastructure | B54: 0 | C54: Assumes use of the existing reference/staging environment already budgeted in the platform cost model (Prior_Auth_Cost_Model V2.0.xlsx); no incremental hosting cost assumed.
A55: External Fees Subtotal: | B55: =SUM(B49:B54) -> 51000
...

Sheet AI Impact Analysis
A1: AI Impact Analysis — Cost & Effort With vs. Without Claude
A2: Each task rated on how much of the work an AI agent (Claude) can execute directly, vs. requires a human owner. Rates pulled from the Time & Cost Summary tab. Third-party/vendor fees are unaffected by AI use and are not shown here.
A4: AI Feasibility Categories
A5: Full Automation | B5: Claude can execute the task end-to-end (run tests, write/fix code, generate reports) with only light human review.
A6: AI-Assisted | B6: Claude materially speeds up the work, but a human must still decide, judge, or coordinate part of it.
A7: Human-Required | B7: Inherently human: signatures, contracts, vendor relationships, live witnessed sessions. Claude can draft supporting material only.
A9: Task-Level Comparison
A10: ID | B10: Task | C10: Owner Role | D10: AI Feasibility | E10: Days (No AI) | F10: Days (With AI) | G10: Cost (No AI, $) | H10: Cost (With AI, $) | I10: Savings ($)
A11: 0.1 | B11: Confirm target IG versions & lock scope | C11: Tech Lead | D11: AI-Assisted | E11: 2 | F11: 0.5 | G11: =E11*INDEX('Time & Cost Summary'!$B$6:$B$15,MATCH(C11,'Time & Cost Summary'!$A$6:$A$15,0)) -> 2900 | H11: =F11*INDEX('Time & Cost Summary'!$B$6:$B$15,MATCH(C11,'Time & Cost Summary'!$A$6:$A$15,0)) -> 725 | I11: =G11-H11 -> 2175
A12: 0.2 | B12: Stand up dedicated conformance test environment | C12: Backend/FHIR Engineer 1 | D12: Full Automation | E12: 4 | F12: 1 | G12: =E12*INDEX('Time & Cost Summary'!$B$6:$B$15,MATCH(C12,'Time & Cost Summary'!$A$6:$A$15,0)) -> 4400 | H12: =F12*INDEX('Time & Cost Summary'!$B$6:$B$15,MATCH(C12,'Time & Cost Summary'!$A$6:$A$15,0)) -> 1100 | I12: =G12-H12 -> 3300
A13: 0.3 | B13: Engage trading partner for X12 278/275 testing | C13: Project Manager | D13: Human-Required | E13: 2 | F13: 1.5 | G13: =E13*INDEX('Time & Cost Summary'!$B$6:$B$15,MATCH(C13,'Time & Cost Summary'!$A$6:$A$15,0)) -> 2100 | H13: =F13*INDEX('Time & Cost Summary'!$B$6:$B$15,MATCH(C13,'Time & Cost Summary'!$A$6:$A$15,0)) -> 1575 | I13: =G13-H13 -> 525
A14: 0.4 | B14: Assign conformance owner per suite | C14: Project Manager | D14: Human-Required | E14: 1 | F14: 0.75 | G14: =E14*INDEX('Time & Cost Summary'!$B$6:$B$15,MATCH(C14,'Time & Cost Summary'!$A$6:$A$15,0)) -> 1050 | H14: =F14*INDEX('Time & Cost Summary'!$B$6:$B$15,MATCH(C14,'Time & Cost Summary'!$A$6:$A$15,0)) -> 787.5 | I14: =G14-H14 -> 262.5
A15: 1.1 | B15: Run Inferno US Core Test Kit | C15: Backend/FHIR Engineer 1 | D15: Full Automation | E15: 4 | F15: 1 | G15: =E15*INDEX('Time & Cost Summary'!$B$6:$B$15,MATCH(C15,'Time & Cost Summary'!$A$6:$A$15,0)) -> 4400 | H15: =F15*INDEX('Time & Cost Summary'!$B$6:$B$15,MATCH(C15,'Time & Cost Summary'!$A$6:$A$15,0)) -> 1100 | I15: =G15-H15 -> 3300
A16: 1.2 | B16: Run Inferno SMART App Launch Test Kit | C16: Backend/FHIR Engineer 1 | D16: Full Automation | E16: 2 | F16: 0.5 | G16: =E16*INDEX('Time & Cost Summary'!$B$6:$B$15,MATCH(C16,'Time & Cost Summary'!$A$6:$A$15,0)) -> 2200 | H16: =F16*INDEX('Time & Cost Summary'!$B$6:$B$15,MATCH(C16,'Time & Cost Summary'!$A$6:$A$15,0)) -> 550 | I16: =G16-H16 -> 1650
A17: 1.3 | B17: Run Inferno CARIN Blue Button Test Kit | C17: Backend/FHIR Engineer 2 | D17: Full Automation | E17: 4 | F17: 1 | G17: =E17*INDEX('Time & Cost Summary'!$B$6:$B$15,MATCH(C17,'Time & Cost Summary'!$A$6:$A$15,0)) -> 4400 | H17: =F17*INDEX('Time & Cost Summary'!$B$6:$B$15,MATCH(C17,'Time & Cost Summary'!$A$6:$A$15,0)) -> 1100 | I17: =G17-H17 -> 3300
A18: 1.4 | B18: Remediate & re-run foundational IG failures | C18: Backend/FHIR Engineer 2 | D18: Full Automation | E18: 6 | F18: 2 | G18: =E18*INDEX('Time & Cost Summary'!$B$6:$B$15,MATCH(C18,'Time & Cost Summary'!$A$6:$A$15,0)) -> 6600 | H18: =F18*INDEX('Time & Cost Summary'!$B$6:$B$15,MATCH(C18,'Time & Cost Summary'!$A$6:$A$15,0)) -> 2200 | I18: =G18-H18 -> 4400
A19: 2.1 | B19: Run Inferno Da Vinci CRD Test Kit | C19: Backend/FHIR Engineer 1 | D19: Full Automation | E19: 6 | F19: 1.5 | G19: =E19*INDEX('Time & Cost Summary'!$B$6:$B$15,MATCH(C19,'Time & Cost Summary'!$A$6:$A$15,0)) -> 6600 | H19: =F19*INDEX('Time & Cost Summary'!$B$6:$B$15,MATCH(C19,'Time & Cost Summary'!$A$6:$A$15,0)) -> 1650 | I19: =G19-H19 -> 4950
A20: 2.2 | B20: Run Inferno Da Vinci DTR Test Kit | C20: Backend/FHIR Engineer 2 | D20: Full Automation | E20: 6 | F20: 1.5 | G20: =E20*INDEX('Time & Cost Summary'!$B$6:$B$15,MATCH(C20,'Time & Cost Summary'!$A$6:$A$15,0)) -> 6600 | H20: =F20*INDEX('Time & Cost Summary'!$B$6:$B$15,MATCH(C20,'Time & Cost Summary'!$A$6:$A$15,0)) -> 1650 | I20: =G20-H20 -> 4950
A21: 2.3 | B21: Run Inferno Da Vinci PAS Test Kit | C21: Backend/FHIR Engineer 1 | D21: AI-Assisted | E21: 8 | F21: 3 | G21: =E21*INDEX('Time & Cost Summary'!$B$6:$B$15,MATCH(C21,'Time & Cost Summary'!$A$6:$A$15,0)) -> 8800 | H21: =F21*INDEX('Time & Cost Summary'!$B$6:$B$15,MATCH(C21,'Time & Cost Summary'!$A$6:$A$15,0)) -> 3300 | I21: =G21-H21 -> 5500
A22: 2.4 | B22: Remediate & re-run CRD/DTR/PAS failures | C22: Backend/FHIR Engineer 2 | D22: AI-Assisted | E22: 10 | F22: 4 | G22: =E22*INDEX('Time & Cost Summary'!$B$6:$B$15,MATCH(C22,'Time & Cost Summary'!$A$6:$A$15,0)) -> 11000 | H22: =F22*INDEX('Time & Cost Summary'!$B$6:$B$15,MATCH(C22,'Time & Cost Summary'!$A$6:$A$15,0)) -> 4400 | I22: =G22-H22 -> 6600
... A36: 5.3 | B36: Establish recurring re-test cadence | C36: Project Manager | D36: AI-Assisted | E36: 1 | F36: 0.5 | G36: =E36*INDEX('Time & Cost Summary'!$B$6:$B$15,MATCH(C36,'Time & Cost Summary'!$A$6:$A$15,0)) -> 1050 | H36: =F36*INDEX('Time & Cost Summary'!$B$6:$B$15,MATCH(C36,'Time & Cost Summary'!$A$6:$A$15,0)) -> 525 | I36: =G36-H36 -> 525
A38: Rationale by Task
A39: ID | B39: Rationale
A40: 0.1 | B40: Claude can research current IG versions and draft the scope memo; a human still locks scope.
A41: 0.2 | B41: Environment/config work an agent can execute directly (env vars, cutover config, verification checks); engineer reviews before touching a live-adjacent backbone.
A42: 0.3 | B42: Business relationship/outreach; Claude can draft the engagement email and test agreement.
A43: 0.4 | B43: Internal people/organizational decision.
A44: 1.1 | B44: Claude can run the test kit, parse results, and produce the pass/fail report end-to-end.
A45: 1.2 | B45: Same as above — mechanical test execution and reporting.
A46: 1.3 | B46: Same as above.
A47: 1.4 | B47: Claude can diagnose failures, write and test fixes, and re-run the suite; engineer reviews non-trivial fixes.
A48: 2.1 | B48: Mechanical test execution and reporting.
A49: 2.2 | B49: Mechanical test execution and reporting.
A50: 2.3 | B50: PAS kit is still in draft/preliminary status on ONC's side — expect kit quirks that need engineer judgment alongside AI execution.
... A65: 5.3 | B65: Claude can draft the schedule/automation; a human approves the cadence policy.
A68: Cost Comparison Summary
B69: Without AI | C69: With AI | D69: Savings | E69: Savings %
A70: Internal Labor | B70: =SUM(G11:G36) -> 130200 | C70: =SUM(H11:H36) -> 56750 | D70: =B70-C70 -> 73450 | E70: =D70/B70 -> 0.5641321
A71: External / Third-Party Fees (unaffected by AI) | B71: ='Time & Cost Summary'!B55 -> 51000 | C71: ='Time & Cost Summary'!B55 -> 51000 | D71: =B71-C71 -> 0 | E71: —
A72: GRAND TOTAL | B72: =B70+B71 -> 181200 | C72: =C70+C71 -> 107750 | D72: =B72-C72 -> 73450 | E72: =D72/B72 -> 0.4053532
...
