Workbook

Sheet Assumptions
A1: WA CIE — optimized delivery plan
A2: Joint Connect360 + WPCO response. Every cost on every sheet derives from B7/B8/B9. Blue = input. Yellow = replace before issue.
B4: LABOUR BASIS
A5: A1 | B5: US-ONLY DELIVERY | C5: RFP Sec. 3.6.4: 'All services under the resulting contract, by the Contractor and any Subcontractors at any tier, must be performed within the United States or its territories.' NO OFFSHORE CONTENT IS PERMITTED. The prior estimate's 54.3% offshore blend is void for this bid.
A6: A2 | B6: US territories allowed | C6: Puerto Rico and Guam are US territories and are the only legitimate low-cost lever. The mix in A5 assumes a US delivery centre in a lower-cost US location or territory.
A7: A3 | B7: 30000 | C7: US delivery centre rate, $/FTE-month. ASSUMPTION - REPLACE WITH RATE CARD. No rate card has been supplied; the prior plan's rates were marked ILLUSTRATIVE.
A8: A4 | B8: 45000 | C8: Onshore premium rate, $/FTE-month. From the prior plan's Assumptions tab, also marked ILLUSTRATIVE.
A9: A5 | B9: 0.55 | C9: Share of effort delivered from the US delivery centre. Key personnel, SMEs, architects and client-facing roles are onshore premium.
A10: A6 | B10: =Assumptions!$B$9*Assumptions!$B$7+(1-Assumptions!$B$9)*Assumptions!$B$8 -> 36750 | C10: Blended US rate, $/FTE-month. Computed: A5 x A3 + (1-A5) x A4.
B11: COMMERCIAL
A12: A7 | B12: 0.1 | C12: Target gross margin, blended across the five years. CY2027 carries a lower margin because it is the ceiling-constrained year; CY2028-31 carry more.
A13: A8 | B13: 530000 | C13: CY2027 non-labour: Connect360 internal chargeback + Azure consumption + third-party assessor fees + travel (travel is inside the firm-fixed price per Sec. 3.6.4 and is not separately payable).
A14: A9 | B14: 480000 | C14: CY2028-31 non-labour, per year, same components.
B15: SCOPE
A16: A10 | B16: CIE, not payer | C16: The prior plan was built for a health payer. Zero occurrences of claims adjudication, 837/835, HCC/CDPS, DRG grouping, HEDIS, prior authorisation, CMS-0057-F or payer-to-payer exchange appear anywhere in the RFP, the ConOps or the 212 requirements. X12 appears once, as one of several payload formats an adapter must transform, with 'or equivalent' in the acceptance criterion.
A17: A11 | B17: Connect360 is pre-existing | C17: The platform exists before contract signature. Washington pays for configuration, integration, implementation and operations - not for building it. This is both the commercial position and the only posture that keeps the offshore-built platform lawful under A1.
A18: A12 | B18: Configuration case | C18: The plan below assumes six gate tests PASS (see Gate tests sheet). If they fail, the CY2027 scope is the construction case and it is $4.3M-$6.3M over the annual ceiling. The tests cost hours and decide $2,205,000.
A19: A13 | B19: 103 of 146 MVP | C19: 103 functional requirements carry a Phase 1 / MVP tag, due 30 June 2027. The largest MVP family is referral management (15). Population-health analytics is named in writing as Phase 2. Client portal and event notification are Phase 3.
A20: A14 | B20: All 66 NFRs are MVP | C20: RFP Sec. 3.5.1: the non-functional requirements are all included in the MVP. Security, consent segmentation, access control, audit, accessibility and performance cannot be phased. 99.5% API availability applies from MVP with no ramp.
B21: CONSTRAINTS TAKEN AS GIVEN
A22: A15 | B22: Hard annual ceilings | C22: CY2027 $3.4M, CY2028 $3.4M, CY2029-31 $3.5M each. Exceeding an annual ceiling may be deemed nonresponsive and may not be scored.
A23: A16 | B23: Two-year term | C23: Initial term 4 Jan 2027 - 4 Jan 2029. Three one-year renewals at Comagine's sole discretion; the Contractor has no right or expectation of renewal. CY2029-31 revenue is an option, not a commitment.
A24: A17 | B24: Cost = 300 of 1000 points | C24: Scored as (lowest evaluated cost / ours) x 300 over the full five-year potential period. Every amortisation dollar is score loss.
A25: A18 | B25: Certification gates go-live | C25: Current HITRUST and SOC 2 certifications plus vulnerability scan and penetration test reports are required BEFORE MVP launch and annually. Failure to pass WaTech's Security Design Review permits immediate termination at no cost to the state.
A26: A19 | B26: Section 701 gates cash | C26: Milestone gates and budget approvals before future funds release, with withholding of payment as a named remedy. No advance or mobilisation payment provision exists in the RFP.
A27: A20 | B27: Directory may be carved out | C27: Sec. 3.1: 'WA CIE is currently in discussions with a statewide directory partner to provide resource directory services.' Gate test G5.

Sheet Revision log
A1: Revision log — every line of the payer plan, dispositioned
A2: KEEP = stays in MVP · MOVE = was scheduled later, now MVP · DEFER = later RFP phase · DELETE = no WA CIE buyer at any phase · ADD = not in the original plan
A4: Original plan activity | B4: Wave | C4: Wks | D4: Disposition | E4: New phase | F4: Reason
A5: Improve storyboard / demo pills / field collateral by persona | B5: W0 | C5: 10 | D5: MOVE | E5: Pre-award | F5: Becomes the 16-20 Nov 2026 demonstration - 350 of 1000 points, scenarios supplied by Comagine. Pre-award investment, not contract scope.
A6: Integrated data-spine design - canonical model, identity contract, FHIR profile, terminology | B6: W1 | C6: 3 | D6: KEEP | E6: CY2027 | F6: Re-scoped to CIE: US Core + SDOHCC, no payer canonical claims model.
A7: Interface contracts + fixtures (Connect360 integration) | B7: W1 | C7: 3 | D7: KEEP | E7: CY2027 | F7: Becomes the owned, versioned participant integration facade.
A8: Steel thread - ingest, conform, project graph, engines, agent wave, E2E | B8: W1 | C8: 18 | D8: KEEP | E8: CY2027 | F8: Re-pointed at the CIE thread: intake, consent, identity, referral, directory, status.
A9: Integrate Connect360 EMPI over PIX / PDQ; matching, survivorship, steward workflow | B9: W1 | C9: 11 | D9: KEEP | E9: CY2027 | F9: RED-UNVERIFIED. No $match, no PIX, no PDQ at the gateway; the EMPI rests on a verbal statement. Gate test G6.
A10: Terminology & value-set load (ICD-10, CPT/HCPCS, LOINC, SNOMED, RxNorm, NDC, CVX, CDT, Gravity) | B10: W1 | C10: 8 | D10: REDUCE | E10: CY2027 | F10: Payer code systems deleted. Retained: LOINC, SNOMED, Gravity/SDOHCC, AIRS taxonomy, referral reason codes.
A11: Source onboarding & connectivity (SFTP/API/stream, trading partner, feed SLA) | B11: W1 | C11: 7 | D11: KEEP | E11: CY2027 | F11: Becomes the 6-8 partner onboarding factory.
A12: Multi-format parse & structural validation (X12 834/837/835/270-271/276-277/278, NCPDP, SNIP) | B12: W1 | C12: 9 | D12: DELETE | E12: - | F12: No claims adjudication anywhere in WA CIE scope. X12 appears once as a transform format with 'or equivalent' permitted.
A13: Raw land + provenance capture (per-record source attribution) | B13: W1 | C13: 5 | D13: KEEP | E13: CY2027 | F13: IRREVERSIBLE. Provenance cannot be backfilled; RFP D7 requires lineage, stewardship and source-to-target mapping.
A14: Adapters - build the in-scope source set | B14: W1 | C14: 13 | D14: REDUCE | E14: CY2027 | F14: CIE sources: CCH and CBO systems, HMIS, clinical, MCO referral platforms. Not claims feeds.
A15: Corrections / voids / adjustments / late & out-of-order handling | B15: W1 | C15: 9 | D15: DELETE | E15: - | F15: Claims-lifecycle concern. No CIE analogue.
A16: Quarantine / DLQ + operator queues + reconciliation / control totals | B16: W1 | C16: 11 | D16: REDUCE | E16: CY2027 | F16: Retained at CIE volume; operator surface folded into the participant portal.
... A47: v1 WPCO overview & population dashboards | B47: W2 | C47: 7 | D47: DEFER | E47: CY2028 | F47: RFP names population-level and equity insights as Phase 2 in writing.
A48: v1 Supporting agents - risk & gap detection | B48: W2 | C48: 5 | D48: DEFER | E48: CY2031
A49: v2 Social-needs / SDOH index & dashboards + regional / cohort views | B49: W2 | C49: 7 | D49: DEFER | E49: CY2028 | F49: Folded into the Phase 2 population & equity analytics line.
A50: v2 Population segmentation & funnel | B50: W2 | C50: 7 | D50: DEFER | E50: CY2028
A51: v3 Total cost of care + outcomes linkage | B51: W2 | C51: 9 | D51: DELETE | E51: - | F51: Payer financial analytics.
A52: v3 Executive dashboard + braided funding / shared-savings | B52: W2 | C52: 9 | D52: DELETE | E52: - | F52: Payer financial analytics.
A53: v1 Care-manager worklist + whole-person care plan | B53: W3 | C53: 9 | D53: SPLIT | E53: CY2027/28 | F53: The WORKLIST is MVP and sits inside the participant portal. The SHARED, MULTI-ORGANISATION CARE PLAN is RFP Phase 2 and needs element-level attribution designed at MVP.
A54: v1 Panel & cohort + MD SMART launch (EMR-embedded) | B54: W3 | C54: 9 | D54: DELETE | E54: - | F54: $506,250. EHR-embedded SMART launch is not a WA CIE MVP requirement; MVP partners are CBO and HMIS systems more than EHRs.
A55: v1 Supporting agents - care management | B55: W3 | C55: 7 | D55: DEFER | E55: CY2031
A56: v2 Episodes + care team & specialist inbox | B56: W3 | C56: 9 | D56: DEFER | E56: CY2028 | F56: Care team is MVP (inside the portal); episodes are later.
A57: v2 Universal task routing & inbox | B57: W3 | C57: 7 | D57: MOVE | E57: CY2027 | F57: Cross-organisation referral routing IS the MVP. 15 MVP requirements.
A58: v3 AI care plan depth + gain-share / shared-savings hooks | B58: W3 | C58: 9 | D58: SPLIT | E58: CY2031 | F58: AI care plan deferred to CY2031. Gain-share DELETED - payer scope.
A59: v3 Cross-team coordination & escalation | B59: W3 | C59: 7 | D59: MOVE | E59: CY2027 | F59: Cross-organisation escalation and SLA is MVP referral behaviour.
A60: v1 Referral tracking + referral journey tracker (7 stages + audit) | B60: W4 | C60: 9 | D60: MOVE | E60: CY2027 | F60: THE LARGEST INVERSION. Scheduled at week 34-42 in the payer plan; it is the single largest MVP family in the RFP and must ship by 30 June 2027.
A61: v1 Care-gap closure & verification - evidence chain | B61: W4 | C61: 11 | D61: REDUCE | E61: CY2027 | F61: Retained as referral closure with a provenance evidence chain. Care-GAP closure deleted with the measures scope.
A62: v2 Social-needs screening (PRAPARE) + program eligibility / benefit enrollment | B62: W4 | C62: 9 | D62: MOVE | E62: CY2027 | F62: MVP. AHC-HRSN already runs live on Connect360, so this is largely configuration. Benefit ENROLMENT deleted.
A63: v2 CBO directory federated with state CIE (Gravity / 360X), closed-loop | B63: W4 | C63: 9 | D63: MOVE | E63: CY2027 | F63: MVP capability. Subject to gate test G5 - the statewide directory partner may supply the corpus.
A64: v3 BH & crisis pathway (988 / CSU / Mobile / ED + post-crisis linkage) | B64: W4 | C64: 9 | D64: DEFER | E64: CY2030 | F64: Not in the MVP capability list.
A65: v3 Risk-adjustment coding gaps (RAF + CDPS) + quality-gap attribution | B65: W4 | C65: 7 | D65: DELETE | E65: - | F65: Payer risk adjustment.
A66: Wave 5 - super-orchestration, live dispatch, agentic marketplace, family thread, agent ROI | B66: W5 | C66: 56 | D66: DEFER | E66: CY2030/31 | F66: Partially fits CY2030-31. The marketplace, family thread and agent ROI reporting DO NOT FIT the five-year envelope at all.
A67: Engine learning & feedback loop; agent policy tuning | B67: Improve | C67: 102 | D67: DEFER | E67: CY2029+ | F67: Requires outcome data that does not exist until after MVP.
A68: Programme governance & delivery; continuous integration & steel-thread harness | B68: Cross | C68: 142 | D68: KEEP | E68: All years | F68: Becomes the 23 contract deliverables, bi-weekly plan updates, monthly reports and the RAID log.
A69: CMS-0057-F optional bucket | B69: Opt | D69: DELETE | E69: - | F69: $545,050. A CIE is not an impacted payer under CMS-0057-F.
A70: Prior-Auth / Coverage / Financial Clearance optional bucket | B70: Opt | D70: DELETE | E70: - | F70: $1,004,750. Payer utilisation management.
A72: NEW SCOPE — not in the original plan
...

Sheet Gantt
A1: WA CIE — Work Breakdown (Gantt), CY2027 MVP
A2: Contract start 4 Jan 2027 = week 1. MVP go-live 30 June 2027 = week 26. Weeks axis. Tier 1 and Tier 2 must COMPLETE before partner onboarding begins — once 6-8 organisations hold production integrations against a surface it cannot be taken away. The certification lane runs from week 1 because HITRUST r2 is not a 25-week path.
A4: Activity | B4: Tier | C4: FTE-mo | D4: Wks | E4: 1 | F4: 2 | G4: 3 | H4: 4 | I4: 5 | J4: 6 | K4: 7 | L4: 8 | M4: 9 | N4: 10 | O4: 11 | P4: 12 | Q4: 13 | R4: 14 | S4: 15 | T4: 16 | U4: 17 | V4: 18 | W4: 19 | X4: 20 | Y4: 21 | Z4: 22 | AA4: 23 | AB4: 24 | AC4: 25 | AD4: 26 | AE4: 27 | AF4: 28 | AG4: 29 | AH4: 30 | AI4: 31 | AJ4: 32 | AK4: 33 | AL4: 34
A5: Identity — stable CIE ID, source-ID retention, non-destructive merge/unmerge, link history, stewardship queue | B5: T1 | C5: 3 | D5: 14
A6: Consent — provision shape, enforcement verification, revoke-not-delete, securityLabel on write | B6: T1 | C6: 2.5 | D6: 12
A7: Provenance per write, cross-org read audit, retention & legal hold, non-human actor | B7: T1 | C7: 1 | D7: 10
A8: RBAC & delegated organisation administration | B8: T1 | C8: 1.5 | D8: 11
A9: Event log — stable type vocabulary, idempotency, ordering, 3-5 subscriptions exposed | B9: T1 | C9: 1.5 | D9: 11
A10: Owned versioned integration facade (US Core + SDOHCC) | B10: T2 | C10: 3 | D10: 11
A11: Domain-verb mutations + statewide reason-code vocabulary | B11: T2 | C11: 3 | D11: 10
A12: MILESTONE — contract surfaces frozen; partner onboarding may begin | B12: ◆ | D12: 1
A13: Conform & write — CIE source set (profiles, conditional-create, Provenance) | B13: T3 | C13: 4 | D13: 13
A14: citizenEverything composite resolver (tenant-scoped, consent-filtered) | B14: T3 | C14: 2.5 | D14: 9
A15: Read-side reporting projection + operational counts + participant extract | B15: T3 | C15: 5 | D15: 13
A16: Participant portal — extend the existing Connect360 portal to worker roles | B16: T3 | C16: 8 | D16: 17
A17: Directory federation adapter (statewide partner supplies the corpus) | B17: T3 | C17: 2 | D17: 9
A18: Referral management configuration & cross-organisation workflow | B18: T3 | C18: 2 | D18: 10
A19: HRSN screening configuration (AHC-HRSN already live) | B19: T3 | C19: 1 | D19: 5
A20: Accessibility — 508 / WCAG 2.1 AA, VPAT / ACR, remediation | B20: T4 | C20: 3 | D20: 16
A21: Tribal & IHS data sovereignty handling and governance | B21: T4 | C21: 1.5 | D21: 15
A22: Certification — HITRUST / SOC 2 evidence, penetration test, WaTech SDR + PTA | B22: NB | C22: 4 | D22: 24
A23: MILESTONE — WaTech Security Design Review passed (gates all HCA data) | B23: ◆ | D23: 1
A24: Partner integration & onboarding factory (6-8 interoperability partners) | B24: NB | C24: 10 | D24: 13
A25: Programme management, governance, 23 deliverables, RAID, reporting cadence | B25: NB | C25: 8 | D25: 34
A26: MILESTONE — MVP GO-LIVE (30 June 2027) | B26: ◆ | D26: 1
A27: Operations & tier-2/3 support (Comagine owns tier 1) | B27: NB | C27: 5 | D27: 9
A28: MILESTONE — end of MVP implementation period (go-live + 60 days) | B28: ◆ | D28: 1
A29: CY2027 TOTAL | C29: =SUM(C5:C28) -> 71.5
A31: LEGEND
A32: T1 Irreversible — the write path. T2 Contract surfaces. T3 MVP product. T4 Compliance engineering. NB Non-build (certification, onboarding, PM, operations).
A33: Weeks 27-34 continue into H2 2027; CY2028-31 activity is on the Phase plan sheet.
A34: DELETED from the prior payer plan and therefore absent here: claims / X12 / NCPDP spine, corrections and voids, coding verification, HCC/CDPS and DRG groupers, HEDIS load, total cost of care, gain-share, CMS-0057-F, prior authorisation, Epic/Cerner SMART launch, the ADF / Databricks secondary path, and the deployable-asset packaging. See the Revision log sheet for the full disposition of every original line.

Sheet Staffing
A1: WA CIE — Staffing by Role, CY2027
A2: US-ONLY delivery (RFP Sec. 3.6.4). Key Personnel named in RFP Table 4 are onshore premium and carry hard minimum qualifications. Costs are shown at the blended rate from Assumptions because no role-level rate card has been supplied; the Location column states the intended mix.
A4: Role | B4: Key Personnel (RFP Table 4) | C4: Delivery location | D4: FTE-months | E4: Cost at blended rate | F4: Notes
A5: Engagement / programme lead | B5: Program Manager | C5: Onshore premium | D5: 5 | E5: =D5*Assumptions!$B$10 -> 183750 | F5: 3 yrs in last 5 leading a comparable health or human-services program team
A6: Delivery / project manager | B6: Project Manager | C6: Onshore premium | D6: 3 | E6: =D6*Assumptions!$B$10 -> 110250 | F6: 3 yrs in last 5 managing comparable delivery with iterative experience
A7: Product manager | B7: Product Manager | C7: Onshore premium | D7: 2 | E7: =D7*Assumptions!$B$10 -> 73500 | F7: 5 yrs owning product direction for a configurable or SaaS solution
A8: Solution architect / technical lead | B8: Technical Lead / Architect | C8: Onshore premium | D8: 7 | E8: =D8*Assumptions!$B$10 -> 257250 | F8: 7 yrs interoperable solution architecture; FHIR, HL7 or Gravity; WaTech conformance
A9: Multi-sector interoperability SME | B9: Multi-Sector Interop SME | C9: Onshore premium | D9: 3 | E9: =D9*Assumptions!$B$10 -> 110250 | F9: 5 yrs cross-sector exchange; bidirectional partner connections and interface governance
A10: Data architect / identity lead | B10: Data Architect / Data Eng Lead | C10: Onshore premium | D10: 3 | E10: =D10*Assumptions!$B$10 -> 110250 | F10: 5 yrs PII/PHI at scale; identity resolution, record linkage, consent-specific access
A11: Security & compliance lead | C11: Onshore premium | D11: 5 | E11: =D11*Assumptions!$B$10 -> 183750 | F11: Certification lane, WaTech SDR, Privacy Threshold Analysis, annual recertification
A12: Social-care / CIE domain SME | C12: Onshore premium | D12: 2 | E12: =D12*Assumptions!$B$10 -> 73500 | F12: HRSN screening, referral practice, CBO and CCH workflow
A13: Accessibility specialist | C13: Onshore premium | D13: 1.5 | E13: =D13*Assumptions!$B$10 -> 55125 | F13: 508 / WCAG 2.1 AA conformance, VPAT / ACR production
A14: Tribal liaison / policy SME | C14: Onshore premium | D14: 1 | E14: =D14*Assumptions!$B$10 -> 36750 | F14: Tribal and IHS data sovereignty; 29 federally recognised tribes in Washington
A15: FHIR / conform engineer | C15: US delivery centre | D15: 8 | E15: =D15*Assumptions!$B$10 -> 294000 | F15: Profiles, conditional-create, provenance, domain verbs, integration facade
A16: Data / integration engineer | C16: US delivery centre | D16: 8 | E16: =D16*Assumptions!$B$10 -> 294000 | F16: Source connectivity, conform pipeline, read-side projection, partner onboarding
A17: Front-end / application engineer | C17: US delivery centre | D17: 8 | E17: =D17*Assumptions!$B$10 -> 294000 | F17: NEW ROLE — the prior staffing model contained no front-end engineering role at all
A18: QA / test engineer | C18: US delivery centre | D18: 5 | E18: =D18*Assumptions!$B$10 -> 183750 | F18: Functional, regression, accessibility and partner integration testing
A19: Platform / DevSecOps engineer | C19: US delivery centre | D19: 4 | E19: =D19*Assumptions!$B$10 -> 147000 | F19: Environments, CI/CD, observability, release
A20: UX / product designer | C20: US delivery centre | D20: 3 | E20: =D20*Assumptions!$B$10 -> 110250 | F20: Worker-facing portal, consent capture, referral workflow
A21: Test / conformance & DQ engineer | C21: US delivery centre | D21: 3 | E21: =D21*Assumptions!$B$10 -> 110250 | F21: Profile binding verification, consent enforcement matrix, data-quality rules
A22: CY2027 TOTAL | D22: =SUM(D5:D21) -> 71.5 | E22: =SUM(E5:E21) -> 2627625
A24: Delivery-location mix check | D24: =SUMIF(C5:C21,"US delivery centre",D5:D21)/D22 -> 0.54545455 | F24: Derived from the role plan. Compare with assumption A5 on the Assumptions sheet; a variance of more than two points means the role plan and the rate assumption disagree.
A26: NO OFFSHORE CONTENT. RFP Sec. 3.6.4: all services, by the Contractor and any Subcontractors at any tier, must be performed within the United States or its territories. Work performed outside the US without prior written approval is a material breach and may result in termination.
A27: Puerto Rico and Guam are US territories and are the only legitimate low-cost lever. The US delivery centre rate is an ASSUMPTION pending the rate card.
A28: Every individual proposed as Key Personnel needs a resume submitted with Submittal Form B and must meet the stated minimum qualifications.

Sheet Cost by Scope
A1: WA CIE — Effort & Cost by Scope
A2: One rate basis, US-only. CY2027 reconciles to the CY2027 MVP sheet and to Staffing. CY2028-31 are scoped to each year's ceiling. Renewal years are options at Comagine's sole discretion, not commitments.
A4: Scope | B4: FTE-months | C4: Labour cost | D4: Non-labour | E4: Delivered cost | F4: Price at target margin | G4: Annual ceiling
A5: CY2027 — MVP to 30 June 2027 (committed term) | B5: 71.5 | C5: =B5*Assumptions!$B$10 -> 2627625 | D5: =Assumptions!$B$13 -> 530000 | E5: =C5+D5 -> 3157625 | F5: =E5/(1-Assumptions!$B$12) -> 3508472.2 | G5: 3400000
A6: CY2028 — Phase 2 (committed term) | B6: 65 | C6: =B6*Assumptions!$B$10 -> 2388750 | D6: =Assumptions!$B$14 -> 480000 | E6: =C6+D6 -> 2868750 | F6: =E6/(1-Assumptions!$B$12) -> 3187500 | G6: 3400000
A7: CY2029 — Phase 3 (renewal option 1) | B7: 66 | C7: =B7*Assumptions!$B$10 -> 2425500 | D7: =Assumptions!$B$14 -> 480000 | E7: =C7+D7 -> 2905500 | F7: =E7/(1-Assumptions!$B$12) -> 3228333.3 | G7: 3500000
A8: CY2030 — Phase 3 continued (renewal option 2) | B8: 60 | C8: =B8*Assumptions!$B$10 -> 2205000 | D8: =Assumptions!$B$14 -> 480000 | E8: =C8+D8 -> 2685000 | F8: =E8/(1-Assumptions!$B$12) -> 2983333.3 | G8: 3500000
A9: CY2031 — maturation (renewal option 3) | B9: 58 | C9: =B9*Assumptions!$B$10 -> 2131500 | D9: =Assumptions!$B$14 -> 480000 | E9: =C9+D9 -> 2611500 | F9: =E9/(1-Assumptions!$B$12) -> 2901666.7 | G9: 3500000
A10: COMMITTED TERM (CY2027-28) | B10: =SUM(B5:B6) -> 136.5 | C10: =SUM(C5:C6) -> 5016375 | D10: =SUM(D5:D6) -> 1010000 | E10: =SUM(E5:E6) -> 6026375 | F10: =SUM(F5:F6) -> 6695972.2 | G10: =SUM(G5:G6) -> 6800000
A11: FULL POTENTIAL PERIOD (CY2027-31) — the Evaluated Cost basis | B11: =SUM(B5:B9) -> 320.5 | C11: =SUM(C5:C9) -> 11778375 | D11: =SUM(D5:D9) -> 2450000 | E11: =SUM(E5:E9) -> 14228375 | F11: =SUM(F5:F9) -> 15809306 | G11: =SUM(G5:G9) -> 17300000
A13: Headroom against the five-year envelope | F13: =G11-F11 -> 1490694.4
A14: CY2027 headroom against its own ceiling | F14: =G5-F5 -> -108472.22
A16: EXCLUDED FROM THE ABOVE
A17: Client-facing portal [RFP Phase 3] | B17: 16 | C17: =B17*Assumptions!$B$10 -> 588000
A18: Agentic marketplace & orchestration at scale | B18: 20 | C18: =B18*Assumptions!$B$10 -> 735000
A19: Household / family thread & caregiver intelligence | B19: 8 | C19: =B19*Assumptions!$B$10 -> 294000
A20: Agent impact & agentic ROI reporting | B20: 7 | C20: =B20*Assumptions!$B$10 -> 257250
A21: Does not fit the five-year envelope at all | B21: =SUM(B17:B20) -> 51 | C21: =SUM(C17:C20) -> 1874250
A23: DELETED — no WA CIE buyer at any phase. Named value $2,354,350: Prior-Auth / Coverage / Financial Clearance $1,004,750 · CMS-0057-F $545,050 · Epic / Cerner SMART launch + CDS Hooks $506,250 · ADF / Databricks secondary path $298,300. Plus the claims / X12 / NCPDP spine, HCC/CDPS and DRG groupers, HEDIS load, total cost of care and gain-share, and the deployable-asset packaging.
A24: Evaluated Cost is defined twice in RFP Sec. 5.7 — three components in one version, four in the other, with Year-1 recurring counted both on its own and inside the five-year total. Submit a written clarification before 9 October; it is free and it moves the cost score.
A25: Exceeding an applicable annual funding ceiling may be deemed nonresponsive and may not be scored.

Sheet CY2027 MVP
A1: CY2027 — MVP to 30 June 2027 · CONFIGURATION CASE
A2: Assumes all six gate tests pass. If they fail this becomes the construction case at 184.5 FTE-months — $4.3M to $6.3M over the annual ceiling.
A4: Workstream | B4: FTE-months | C4: Cost | D4: Note
A5: TIER 1 — IRREVERSIBLE. Cannot be retrofitted; these are the write path. | B5: =SUM(B6:B10) -> 9.5 | C5: =SUM(C6:C10) -> 349125 | D5: A capability is safely deferrable if and only if it can be reconstructed from what MVP wrote down. Everything here is write-path: a fact not captured cannot be recovered later. This tier is what makes the graph, the engines and the agents deferrable rather than lost.
A6: Identity: configure matching, stewardship queue, NON-DESTRUCTIVE merge/unmerge with link history | B6: 3 | C6: =B6*Assumptions!$B$10 -> 110250
A7: Consent: policy configuration, enforcement verification, revoke-not-delete fix, securityLabel on write | B7: 2.5 | C7: =B7*Assumptions!$B$10 -> 91875
A8: Provenance per write, cross-org read audit, retention & legal hold, non-human actor representation | B8: 1 | C8: =B8*Assumptions!$B$10 -> 36750
A9: RBAC & delegated organisation administration | B9: 1.5 | C9: =B9*Assumptions!$B$10 -> 55125
A10: Event log: stable type vocabulary, idempotency contract, ordering, 3-5 subscriptions exposed | B10: 1.5 | C10: =B10*Assumptions!$B$10 -> 55125
A11: TIER 2 — CONTRACT SURFACES. Must land before the first partner integrates. | B11: =SUM(B12:B13) -> 6 | C11: =SUM(C12:C13) -> 220500 | D11: Once 6-8 independent organisations hold production integrations against a surface, it cannot be taken away. These are politically irreversible, not technically.
A12: Owned, versioned integration facade (FHIR REST profiled to US Core + SDOHCC) | B12: 3 | C12: =B12*Assumptions!$B$10 -> 110250
A13: Domain-verb mutations for Task / ServiceRequest + statewide reason-code vocabulary | B13: 3 | C13: =B13*Assumptions!$B$10 -> 110250
A14: TIER 3 — THE MVP PRODUCT. 103 of 146 functional requirements, due 30 June 2027. | B14: =SUM(B15:B21) -> 24.5 | C14: =SUM(C15:C21) -> 900375 | D14: Referral management is the largest MVP family at 15 requirements — the line the payer plan scheduled at week 34-42.
A15: Participant portal — EXTEND the existing Connect360 portal to worker roles | B15: 8 | C15: =B15*Assumptions!$B$10 -> 294000
A16: Read-side reporting projection + 6-10 operational counts + participant extract | B16: 5 | C16: =B16*Assumptions!$B$10 -> 183750
A17: Conform & write — CIE source set (profiles, conditional-create, Provenance) | B17: 4 | C17: =B17*Assumptions!$B$10 -> 147000
A18: citizenEverything composite resolver (tenant-scoped, consent-filtered) | B18: 2.5 | C18: =B18*Assumptions!$B$10 -> 91875
A19: Directory federation adapter (statewide partner supplies the corpus) | B19: 2 | C19: =B19*Assumptions!$B$10 -> 73500
A20: Referral management configuration & cross-organisation workflow | B20: 2 | C20: =B20*Assumptions!$B$10 -> 73500
A21: HRSN screening configuration (AHC-HRSN already live on Connect360) | B21: 1 | C21: =B21*Assumptions!$B$10 -> 36750
A22: TIER 4 — COMPLIANCE ENGINEERING. Absent from the prior plan entirely. | B22: =SUM(B23:B24) -> 4.5 | C22: =SUM(C23:C24) -> 165375 | D22: All 66 non-functional requirements are MVP. WaTech standards are mandatory and non-negotiable.
A23: Accessibility: 508 / WCAG 2.1 AA conformance, VPAT / ACR production, remediation | B23: 3 | C23: =B23*Assumptions!$B$10 -> 110250
A24: Tribal & IHS data sovereignty handling and governance | B24: 1.5 | C24: =B24*Assumptions!$B$10 -> 55125
A25: NON-BUILD — the work that is actually paid for under this contract. | B25: =SUM(B26:B29) -> 27 | C25: =SUM(C26:C29) -> 992250 | D25: The prior plan called these rows 'off the asset critical path' and excluded them from the totals. Under WA CIE they ARE the contract.
A26: Certification: evidence assembly, penetration test, WaTech SDR + Privacy Threshold Analysis | B26: 4 | C26: =B26*Assumptions!$B$10 -> 147000
A27: Partner integration & onboarding factory (6-8 interoperability partners) | B27: 10 | C27: =B27*Assumptions!$B$10 -> 367500
A28: Programme management, governance participation, 23 deliverables, RAID, reporting cadence | B28: 8 | C28: =B28*Assumptions!$B$10 -> 294000
A29: Operations & tier-2/3 support (~5 months of CY2027; Comagine owns tier 1) | B29: 5 | C29: =B29*Assumptions!$B$10 -> 183750
A30: TOTAL | B30: =B5+B11+B14+B22+B25 -> 71.5 | C30: =C5+C11+C14+C22+C25 -> 2627625
A32: Sequencing rule: Tier 1 and Tier 2 start week 1 and must complete before partner onboarding begins. Tier 3 follows. The certification lane runs in parallel from week 1 — HITRUST r2 is not a 25-week path, which is why gate test G2 decides whether this plan is deliverable at all.

Sheet Phase plan
A1: Five-year phase plan, right-sized to the annual ceilings
A2: Each year is scoped to what that year's ceiling can fund at the target margin — not to the wish list.
A4: CY | B4: Scope | C4: FTE-mo | D4: Cost | E4: Price | F4: Ceiling | G4: Headroom
B5: MVP — see the CY2027 MVP sheet (configuration case) | C5: ='CY2027 MVP'!$B$30 -> 71.5 | D5: ='CY2027 MVP'!$C$30+Assumptions!$B$13 -> 3157625
A6: 2027 | B6: CY2027 total | C6: =SUM(C5:C5) -> 71.5 | D6: =SUM(D5:D5) -> 3157625 | E6: =D6/(1-Assumptions!$B$12) -> 3508472.2 | F6: 3400000 | G6: =F6-E6 -> -108472.22
B8: Operations, tier-2/3 support, PM, annual recertification | C8: 22 | D8: =C8*Assumptions!$B$10 -> 808500
B9: Next partner cohort onboarding | C9: 12 | D9: =C9*Assumptions!$B$10 -> 441000
B10: Granular consent policy authoring [RFP Phase 2] | C10: 7 | D10: =C10*Assumptions!$B$10 -> 257250
B11: Shared collaborative care plan, element-level attribution [RFP Phase 2] | C11: 12 | D11: =C11*Assumptions!$B$10 -> 441000
B12: Population & equity analytics over the full MVP history [RFP Phase 2] | C12: 12 | D12: =C12*Assumptions!$B$10 -> 441000
A13: 2028 | B13: CY2028 total | C13: =SUM(C8:C12) -> 65 | D13: =SUM(D8:D12)+Assumptions!$B$14 -> 2868750 | E13: =D13/(1-Assumptions!$B$12) -> 3187500 | F13: 3400000 | G13: =F13-E13 -> 212500
B15: Operations, support, PM, recertification | C15: 22 | D15: =C15*Assumptions!$B$10 -> 808500
B16: Event notification ingest / parse / exchange [RFP Phase 3] | C16: 14 | D16: =C16*Assumptions!$B$10 -> 514500
B17: Knowledge graph as a projection — hydrated by REPLAYING the MVP event log | C17: 14 | D17: =C17*Assumptions!$B$10 -> 514500
B18: Journey engine v1 — deterministic timeline over the recorded temporal spine | C18: 8 | D18: =C18*Assumptions!$B$10 -> 294000
B19: WPC context ranking, behind the citizenEverything seam — no partner-facing change | C19: 8 | D19: =C19*Assumptions!$B$10 -> 294000
A20: 2029 | B20: CY2029 total | C20: =SUM(C15:C19) -> 66 | D20: =SUM(D15:D19)+Assumptions!$B$14 -> 2905500 | E20: =D20/(1-Assumptions!$B$12) -> 3228333.3 | F20: 3500000 | G20: =F20-E20 -> 271666.67
B22: Operations, support, PM, recertification | C22: 22 | D22: =C22*Assumptions!$B$10 -> 808500
B23: Real-time dispatch + signal dispositioning engine | C23: 12 | D23: =C23*Assumptions!$B$10 -> 441000
B24: Graph inference, scoring, household & family linkage | C24: 12 | D24: =C24*Assumptions!$B$10 -> 441000
B25: Enrollment verification + remaining change subscriptions | C25: 10 | D25: =C25*Assumptions!$B$10 -> 367500
B26: Directory stewardship model | C26: 4 | D26: =C26*Assumptions!$B$10 -> 147000
A27: 2030 | B27: CY2030 total | C27: =SUM(C22:C26) -> 60 | D27: =SUM(D22:D26)+Assumptions!$B$14 -> 2685000 | E27: =D27/(1-Assumptions!$B$12) -> 2983333.3 | F27: 3500000 | G27: =F27-E27 -> 516666.67
B29: Operations, support, PM, recertification | C29: 22 | D29: =C29*Assumptions!$B$10 -> 808500
B30: Governed agents (HITL) over the MVP domain verbs & actor model | C30: 14 | D30: =C30*Assumptions!$B$10 -> 514500
B31: Care-plan intelligence | C31: 8 | D31: =C31*Assumptions!$B$10 -> 294000
B32: Forecasting & equity monitoring | C32: 8 | D32: =C32*Assumptions!$B$10 -> 294000
B33: Advanced consent interoperability with external networks | C33: 6 | D33: =C33*Assumptions!$B$10 -> 220500
A34: 2031 | B34: CY2031 total | C34: =SUM(C29:C33) -> 58 | D34: =SUM(D29:D33)+Assumptions!$B$14 -> 2611500 | E34: =D34/(1-Assumptions!$B$12) -> 2901666.7 | F34: 3500000 | G34: =F34-E34 -> 598333.33
B36: FIVE-YEAR TOTAL | C36: =C6+C13+C20+C27+C34 -> 320.5 | D36: =D6+D13+D20+D27+D34 -> 14228375 | E36: =E6+E13+E20+E27+E34 -> 15809306 | F36: =F6+F13+F20+F27+F34 -> 17300000 | G36: =G6+G13+G20+G27+G34 -> 1490694.4
B38: DOES NOT FIT THE FIVE-YEAR ENVELOPE AT ALL — needs another funding source or falls away
B39: Client-facing portal [RFP Phase 3] | C39: 16 | D39: =C39*Assumptions!$B$10 -> 588000
B40: Agentic marketplace & orchestration at scale | C40: 20 | D40: =C40*Assumptions!$B$10 -> 735000
B41: Household / family thread & caregiver intelligence | C41: 8 | D41: =C41*Assumptions!$B$10 -> 294000
B42: Agent impact & agentic ROI reporting | C42: 7 | D42: =C42*Assumptions!$B$10 -> 257250
B43: Excluded total | C43: =SUM(C39:C42) -> 51 | D43: =SUM(D39:D42) -> 1874250
B45: Stated plainly: the full WPCO vision does not fit inside the WA CIE envelope even across five fully-phased years. The engines and the graph arrive; the agentic marketplace, the household thread and the client-facing portal do not. If they matter, they need a second funding source — which is the argument for a pipeline, not for loading them into this bid.

Sheet Gate tests
A1: Six tests decide $2.2M of CY2027 scope. None costs more than a day.
A2: Run these BEFORE the cost proposal is priced. Each one moves the plan between the configuration case and the construction case.
A4: Gate | B4: The question | C4: Cost to answer | D4: Decides | E4: Config FTE-mo | F4: Construct FTE-mo | G4: Swing FTE-mo | H4: Swing $ | I4: If it fails
A5: G3 | B5: Can the existing Connect360 portal be extended to worker roles, or is a new worker application required? | C5: Repo review + staff-scoped demo | D5: Participant portal | E5: 8 | F5: 35 | G5: =F5-E5 -> 27 | H5: =G5*Assumptions!$B$10 -> 992250 | I5: The largest single number in the plan. No worker UI has ever been observed and the prior staffing model contained no front-end engineering role at all. A new build is 26 FTE-months of front-end at ONE concurrent engineer, which is the floor and not the estimate.
A6: G2 | B6: Does Connect360 hold current HITRUST r2 and SOC 2 Type II certifications? | C6: One call | D6: Certification lane | E6: 4 | F6: 12 | G6: =F6-E6 -> 8 | H6: =G6*Assumptions!$B$10 -> 294000 | I6: Certification is a contractual pre-condition of MVP launch with an immediate-termination trigger. HITRUST r2 from a standing start is 9-18 months; contract start to MVP is 25 weeks. If the answer is no, this bid needs a certified partner or it cannot be delivered.
A7: G5 | B7: Is the resource directory carved out to the statewide directory partner? | C7: Written question to Comagine by 9 October | D7: Directory | E7: 2 | F7: 12 | G7: =F7-E7 -> 10 | H7: =G7*Assumptions!$B$10 -> 367500 | I7: Sec. 3.1 says Comagine is in discussions with a statewide directory partner. If carved out we federate; if not we own corpus sourcing and curation, which is an operation, not code.
A8: G4 | B8: Does a role / permission model with delegated organisation administration exist? | C8: Schema review | D8: RBAC & delegated admin | E8: 1.5 | F8: 7 | G8: =F8-E8 -> 5.5 | H8: =G8*Assumptions!$B$10 -> 202125 | I8: No role or permission type appears in the 553 introspected types. IAM is a named MVP capability area with 10 MVP requirements and, in a CIE, delegated admin is customer-facing.
A9: G6 | B9: Does matchPerson / resolveIdentity exist behind the gateway, and can it be fronted? | C9: One call | D9: Identity resolution | E9: 3 | F9: 8 | G9: =F9-E9 -> 5 | H9: =G9*Assumptions!$B$10 -> 183750 | I9: There is no $match, no PIX and no PDQ at the gateway, and the EMPI's existence rests on a verbal statement. Client identity management is a named MVP capability and identity is the state's own number-one current-state gap.
A10: G1 | B10: Is provision.securityLabel enforced at QUERY time, not just stored? | C10: One hour | D10: Consent enforcement | E10: 2.5 | F10: 7 | G10: =F10-E10 -> 4.5 | H10: =G10*Assumptions!$B$10 -> 165375 | I10: Write a Consent with a securityLabel, query as a principal outside the provision, see whether the resource is withheld. If it is not, the pipeline writes labels nothing enforces — which is worse than no labelling, because the security representation is carried into the WaTech Security Design Review.
D11: TOTAL DECIDED BY SIX TESTS | E11: =SUM(E5:E10) -> 21 | F11: =SUM(F5:F10) -> 81 | G11: =SUM(G5:G10) -> 60 | H11: =SUM(H5:H10) -> 2205000

Sheet Affordability
A1: What $3,400,000 actually buys in CY2027
A2: Gross margin is the lever that decides whether the configuration case fits. The construction case does not fit at any margin.
A3: Construction-case effort, CY2027 (FTE-months), used in column D: | D3: 184.5
A4: Gross margin | B4: Configuration case price | C4: Headroom vs ceiling | D4: Construction case price | E4: Gap vs ceiling | F4: Affordable effort (FTE-mo)
A5: 0.05 | B5: =('CY2027 MVP'!$C$30+Assumptions!$B$13)/(1-A5) -> 3323815.8 | C5: =3400000-B5 -> 76184.211 | D5: =($D$3*Assumptions!$B$10+Assumptions!$B$13)/(1-A5) -> 7695131.6 | E5: =3400000-D5 -> -4295131.6 | F5: =(3400000*(1-A5)-Assumptions!$B$13)/Assumptions!$B$10 -> 73.469388
A6: 0.075 | B6: =('CY2027 MVP'!$C$30+Assumptions!$B$13)/(1-A6) -> 3413648.6 | C6: =3400000-B6 -> -13648.649 | D6: =($D$3*Assumptions!$B$10+Assumptions!$B$13)/(1-A6) -> 7903108.1 | E6: =3400000-D6 -> -4503108.1 | F6: =(3400000*(1-A6)-Assumptions!$B$13)/Assumptions!$B$10 -> 71.156463
A7: 0.1 | B7: =('CY2027 MVP'!$C$30+Assumptions!$B$13)/(1-A7) -> 3508472.2 | C7: =3400000-B7 -> -108472.22 | D7: =($D$3*Assumptions!$B$10+Assumptions!$B$13)/(1-A7) -> 8122638.9 | E7: =3400000-D7 -> -4722638.9 | F7: =(3400000*(1-A7)-Assumptions!$B$13)/Assumptions!$B$10 -> 68.843537
A8: 0.15 | B8: =('CY2027 MVP'!$C$30+Assumptions!$B$13)/(1-A8) -> 3714852.9 | C8: =3400000-B8 -> -314852.94 | D8: =($D$3*Assumptions!$B$10+Assumptions!$B$13)/(1-A8) -> 8600441.2 | E8: =3400000-D8 -> -5200441.2 | F8: =(3400000*(1-A8)-Assumptions!$B$13)/Assumptions!$B$10 -> 64.217687
A9: 0.2 | B9: =('CY2027 MVP'!$C$30+Assumptions!$B$13)/(1-A9) -> 3947031.2 | C9: =3400000-B9 -> -547031.25 | D9: =($D$3*Assumptions!$B$10+Assumptions!$B$13)/(1-A9) -> 9137968.8 | E9: =3400000-D9 -> -5737968.8 | F9: =(3400000*(1-A9)-Assumptions!$B$13)/Assumptions!$B$10 -> 59.591837
A10: 0.25 | B10: =('CY2027 MVP'!$C$30+Assumptions!$B$13)/(1-A10) -> 4210166.7 | C10: =3400000-B10 -> -810166.67 | D10: =($D$3*Assumptions!$B$10+Assumptions!$B$13)/(1-A10) -> 9747166.7 | E10: =3400000-D10 -> -6347166.7 | F10: =(3400000*(1-A10)-Assumptions!$B$13)/Assumptions!$B$10 -> 54.965986
A12: READ THIS ROW BY ROW.
A13: The configuration case fits CY2027 at roughly 7% gross margin and is about $108,000 over at 10%. That is a real, closeable gap — three FTE-months of scope, or a thinner year-one margin recovered in CY2028-31 where there is headroom.
A14: The construction case is $4.3M to $6.3M over the CY2027 ceiling at every margin tested. There is no pricing structure that recovers it. Exceeding an annual ceiling may be deemed nonresponsive and may not be scored.
A16: Two structural facts behind these numbers, both from the RFP:
A17: Sec. 3.6.4 — all services must be performed within the United States or its territories. The prior estimate's 54.3% offshore blend is void. At 100% onshore premium the prior committed number rises from $5,093,845 to $8,023,500 and Position B from $6,316,265 to $10,573,650.
A18: Evaluated Cost is defined twice in Sec. 5.7, once with three components and once with four — and in the four-component version Year-1 M&O and subscription are counted separately AND inside the full five-year recurring total. Recurring dollars are scored roughly twice, which penalises amortising a platform into subscription at about 2x relative to loading it into implementation milestones. Submit a written clarification; it is free and it moves the score.

Sheet Risks
A1: Open risks carried into the bid
A2: Each one is named, owned and either priced or explicitly excluded. Nothing here is a surprise after signature.
A4: Risk | B4: Exposure | C4: Mitigation / what retires it
A5: No rate card. Both labour rates are ASSUMPTIONS; the prior plan's rates were marked ILLUSTRATIVE and that caveat has now been live across three document versions. | B5: Whole model | C5: Get the real US rate card with a vintage and a named delivery-centre location before the cost proposal is priced. Until then every figure here is directional.
A6: Certification not held. HITRUST r2 and SOC 2 Type II are a pre-condition of MVP launch with an immediate-termination trigger. | B6: 8 FTE-mo, and deliverability | C6: Gate test G2. If Connect360 does not hold them, team with a partner who does — that decision changes Submittal Form A and cannot wait.
A7: Consent enforcement unproven. The provision model exists; query-time enforcement has never been tested. | B7: 4.5 FTE-mo + the security representation | C7: Gate test G1. One hour. Run it before pricing.
A8: No worker application observed anywhere in Connect360 — only API surface. | B8: 27 FTE-mo | C8: Gate test G3. The single largest swing in the plan.
A9: Three MVP capabilities depend on another IBM organisation's unscheduled backlog: the composite resolver, 21 unexposed change subscriptions, and matchPerson / resolveIdentity. | B9: Schedule + credit | C9: Written commitment with dates from the connect360-saas org, or price them as owned. Consuming NATS directly bypasses the proxy, which is the sole enforcer of tenant isolation — so there is no safe workaround.
A10: Two-year term against a five-year plan. CY2029-31 are options at Comagine's sole discretion. | B10: $10.5M of the envelope | C10: Build the investment case on CY2027-28 only. If it does not clear on $6.8M gross, it does not clear.
A11: Section 701 gated funding. Milestone gates and budget approvals before funds release; no advance or mobilisation payment exists in the RFP. | B11: Working capital across H1 2027 | C11: Decompose CY2027 into 8-12 acceptance milestones weighted toward design, SDR pass, environment provisioning and per-partner acceptance. Negotiate subscription billing from environment provisioning rather than go-live.
A12: Cost is 300 of 1000 points on a lowest-price ratio, against a hard annual ceiling. | B12: Up to 88 points | C12: Price the deployment and the operations, not a platform build. Every amortisation dollar is score loss.
A13: MVP date is fixed at 30 June 2027 with 6-8 partner integrations. Integration volume is not a variable that can be phased. | B13: Schedule | C13: The onboarding factory in CY2027 is sized at 10 FTE-months for 6-8 partners. Comparable procurements run $60-90k fully loaded per partner; this is the line most often under-estimated by half.
A14: Tribal and IHS data sovereignty was withdrawn from the prior estimate as geography-specific. | B14: Compliance | C14: RESTORED at 1.5 FTE-months. Washington has 29 federally recognised tribes and the RFP requires compliance with applicable Tribal requirements.
A15: Accessibility and Section 1557 language access were absent from the prior pack entirely. | B15: Compliance + rework | C15: Designed in at 3.0 FTE-months. Retrofitted accessibility across worker surfaces runs 3-5x the cost of designed-in.
A16: Non-labour costs are only partly modelled: Connect360 internal chargeback, Azure consumption, assessor fees and travel are in; terminology licensing, HISP fees and AIRS membership are not. | B16: Unquantified | C16: Build the non-labour register before the cost proposal. The two-rate-cell model is structurally incapable of representing them.
